Workbook

Sheet Yetkilendirme ve Beyan Takip
A1: İL | B1: İLÇE | C1: MAHALLE | D1: ALAN | E1: ADA | F1: PARSEL | G1: Kod | H1: TAPU ID | I1: SATIŞ DURUM | J1: 1. MÜŞTERİ | K1: BEYAN | L1: EİDS YETKİ BİTİŞ | M1: 2. MÜŞTERİ | N1: BEYAN | O1: EİDS YETKİ BİTİŞ | P1: 3. MÜŞTERİ | Q1: BEYAN | R1: EİDS YETKİ BİTİŞ
A2: BALIKESİR | B2: SUSURLUK | C2: REŞADİYE | D2: 303.39 | E2: 159 | F2: 8 | G2: =C2&E2&F2 -> REŞADİYE1598 | I2: =IF(VLOOKUP(G2,'Bereketli Satış'!J:AK,5,0)="","",VLOOKUP(G2,'Bereketli Satış'!J:AK,5,0)) -> #N/A | J2: =IF(VLOOKUP(G2,'Bereketli Satış'!J:AK,28,0)="","",VLOOKUP(G2,'Bereketli Satış'!J:AK,28,0)) -> #N/A | M2: =IF(VLOOKUP(G2,'Bereketli Satış'!J:AK,30,0)="","",VLOOKUP(G2,'Bereketli Satış'!J:AK,30,0)) -> #N/A | P2: =IF(VLOOKUP(G2,'Bereketli Satış'!J:AK,32,0)="","",VLOOKUP(G2,'Bereketli Satış'!J:AK,32,0)) -> #N/A
A3: BALIKESİR | B3: SUSURLUK | C3: REŞADİYE | D3: 312.8 | E3: 158 | F3: 8 | G3: =C3&E3&F3 -> REŞADİYE1588 | I3: =IF(VLOOKUP(G3,'Bereketli Satış'!J:AK,5,0)="","",VLOOKUP(G3,'Bereketli Satış'!J:AK,5,0)) -> #N/A | J3: =IF(VLOOKUP(G3,'Bereketli Satış'!J:AK,28,0)="","",VLOOKUP(G3,'Bereketli Satış'!J:AK,28,0)) -> #N/A | M3: =IF(VLOOKUP(G3,'Bereketli Satış'!J:AK,30,0)="","",VLOOKUP(G3,'Bereketli Satış'!J:AK,30,0)) -> #N/A | P3: =IF(VLOOKUP(G3,'Bereketli Satış'!J:AK,32,0)="","",VLOOKUP(G3,'Bereketli Satış'!J:AK,32,0)) -> #N/A
A4: BALIKESİR | B4: SUSURLUK | C4: REŞADİYE | D4: 387.93 | E4: 159 | F4: 7 | G4: =C4&E4&F4 -> REŞADİYE1597 | I4: =IF(VLOOKUP(G4,'Bereketli Satış'!J:AK,5,0)="","",VLOOKUP(G4,'Bereketli Satış'!J:AK,5,0)) -> #N/A | J4: =IF(VLOOKUP(G4,'Bereketli Satış'!J:AK,28,0)="","",VLOOKUP(G4,'Bereketli Satış'!J:AK,28,0)) -> #N/A | M4: =IF(VLOOKUP(G4,'Bereketli Satış'!J:AK,30,0)="","",VLOOKUP(G4,'Bereketli Satış'!J:AK,30,0)) -> #N/A | P4: =IF(VLOOKUP(G4,'Bereketli Satış'!J:AK,32,0)="","",VLOOKUP(G4,'Bereketli Satış'!J:AK,32,0)) -> #N/A
A5: BALIKESİR | B5: SUSURLUK | C5: REŞADİYE | D5: 298 | E5: 163 | F5: 15 | G5: =C5&E5&F5 -> REŞADİYE16315 | I5: =IF(VLOOKUP(G5,'Bereketli Satış'!J:AK,5,0)="","",VLOOKUP(G5,'Bereketli Satış'!J:AK,5,0)) -> #N/A | J5: =IF(VLOOKUP(G5,'Bereketli Satış'!J:AK,28,0)="","",VLOOKUP(G5,'Bereketli Satış'!J:AK,28,0)) -> #N/A | M5: =IF(VLOOKUP(G5,'Bereketli Satış'!J:AK,30,0)="","",VLOOKUP(G5,'Bereketli Satış'!J:AK,30,0)) -> #N/A | P5: =IF(VLOOKUP(G5,'Bereketli Satış'!J:AK,32,0)="","",VLOOKUP(G5,'Bereketli Satış'!J:AK,32,0)) -> #N/A
A6: BALIKESİR | B6: SUSURLUK | C6: REŞADİYE | D6: 406.75 | E6: 159 | F6: 6 | G6: =C6&E6&F6 -> REŞADİYE1596 | I6: =IF(VLOOKUP(G6,'Bereketli Satış'!J:AK,5,0)="","",VLOOKUP(G6,'Bereketli Satış'!J:AK,5,0)) -> #N/A | J6: =IF(VLOOKUP(G6,'Bereketli Satış'!J:AK,28,0)="","",VLOOKUP(G6,'Bereketli Satış'!J:AK,28,0)) -> #N/A | M6: =IF(VLOOKUP(G6,'Bereketli Satış'!J:AK,30,0)="","",VLOOKUP(G6,'Bereketli Satış'!J:AK,30,0)) -> #N/A | P6: =IF(VLOOKUP(G6,'Bereketli Satış'!J:AK,32,0)="","",VLOOKUP(G6,'Bereketli Satış'!J:AK,32,0)) -> #N/A
A7: BALIKESİR | B7: SUSURLUK | C7: REŞADİYE | D7: 283.59 | E7: 169 | F7: 7 | G7: =C7&E7&F7 -> REŞADİYE1697 | I7: =IF(VLOOKUP(G7,'Bereketli Satış'!J:AK,5,0)="","",VLOOKUP(G7,'Bereketli Satış'!J:AK,5,0)) -> #N/A | J7: =IF(VLOOKUP(G7,'Bereketli Satış'!J:AK,28,0)="","",VLOOKUP(G7,'Bereketli Satış'!J:AK,28,0)) -> #N/A | M7: =IF(VLOOKUP(G7,'Bereketli Satış'!J:AK,30,0)="","",VLOOKUP(G7,'Bereketli Satış'!J:AK,30,0)) -> #N/A | P7: =IF(VLOOKUP(G7,'Bereketli Satış'!J:AK,32,0)="","",VLOOKUP(G7,'Bereketli Satış'!J:AK,32,0)) -> #N/A
A8: BALIKESİR | B8: SUSURLUK | C8: REŞADİYE | D8: 283.59 | E8: 169 | F8: 8 | G8: =C8&E8&F8 -> REŞADİYE1698 | I8: =IF(VLOOKUP(G8,'Bereketli Satış'!J:AK,5,0)="","",VLOOKUP(G8,'Bereketli Satış'!J:AK,5,0)) -> #N/A | J8: =IF(VLOOKUP(G8,'Bereketli Satış'!J:AK,28,0)="","",VLOOKUP(G8,'Bereketli Satış'!J:AK,28,0)) -> #N/A | M8: =IF(VLOOKUP(G8,'Bereketli Satış'!J:AK,30,0)="","",VLOOKUP(G8,'Bereketli Satış'!J:AK,30,0)) -> #N/A | P8: =IF(VLOOKUP(G8,'Bereketli Satış'!J:AK,32,0)="","",VLOOKUP(G8,'Bereketli Satış'!J:AK,32,0)) -> #N/A
A9: BALIKESİR | B9: SUSURLUK | C9: REŞADİYE | D9: 510.06 | E9: 178 | F9: 11 | G9: =C9&E9&F9 -> REŞADİYE17811 | I9: =IF(VLOOKUP(G9,'Bereketli Satış'!J:AK,5,0)="","",VLOOKUP(G9,'Bereketli Satış'!J:AK,5,0)) -> #N/A | J9: =IF(VLOOKUP(G9,'Bereketli Satış'!J:AK,28,0)="","",VLOOKUP(G9,'Bereketli Satış'!J:AK,28,0)) -> #N/A | M9: =IF(VLOOKUP(G9,'Bereketli Satış'!J:AK,30,0)="","",VLOOKUP(G9,'Bereketli Satış'!J:AK,30,0)) -> #N/A | P9: =IF(VLOOKUP(G9,'Bereketli Satış'!J:AK,32,0)="","",VLOOKUP(G9,'Bereketli Satış'!J:AK,32,0)) -> #N/A
A10: BALIKESİR | B10: SUSURLUK | C10: REŞADİYE | D10: 349.22 | E10: 158 | F10: 18 | G10: =C10&E10&F10 -> REŞADİYE15818 | I10: =IF(VLOOKUP(G10,'Bereketli Satış'!J:AK,5,0)="","",VLOOKUP(G10,'Bereketli Satış'!J:AK,5,0)) -> #N/A | J10: =IF(VLOOKUP(G10,'Bereketli Satış'!J:AK,28,0)="","",VLOOKUP(G10,'Bereketli Satış'!J:AK,28,0)) -> #N/A | M10: =IF(VLOOKUP(G10,'Bereketli Satış'!J:AK,30,0)="","",VLOOKUP(G10,'Bereketli Satış'!J:AK,30,0)) -> #N/A | P10: =IF(VLOOKUP(G10,'Bereketli Satış'!J:AK,32,0)="","",VLOOKUP(G10,'Bereketli Satış'!J:AK,32,0)) -> #N/A
A11: BALIKESİR | B11: SUSURLUK | C11: REŞADİYE | D11: 740.83 | E11: 162 | F11: 11 | G11: =C11&E11&F11 -> REŞADİYE16211 | I11: =IF(VLOOKUP(G11,'Bereketli Satış'!J:AK,5,0)="","",VLOOKUP(G11,'Bereketli Satış'!J:AK,5,0)) -> #N/A | J11: =IF(VLOOKUP(G11,'Bereketli Satış'!J:AK,28,0)="","",VLOOKUP(G11,'Bereketli Satış'!J:AK,28,0)) -> #N/A | M11: =IF(VLOOKUP(G11,'Bereketli Satış'!J:AK,30,0)="","",VLOOKUP(G11,'Bereketli Satış'!J:AK,30,0)) -> #N/A | P11: =IF(VLOOKUP(G11,'Bereketli Satış'!J:AK,32,0)="","",VLOOKUP(G11,'Bereketli Satış'!J:AK,32,0)) -> #N/A
A12: BALIKESİR | B12: SUSURLUK | C12: REŞADİYE | D12: 537.68 | E12: 162 | F12: 2 | G12: =C12&E12&F12 -> REŞADİYE1622 | I12: =IF(VLOOKUP(G12,'Bereketli Satış'!J:AK,5,0)="","",VLOOKUP(G12,'Bereketli Satış'!J:AK,5,0)) -> #N/A | J12: =IF(VLOOKUP(G12,'Bereketli Satış'!J:AK,28,0)="","",VLOOKUP(G12,'Bereketli Satış'!J:AK,28,0)) -> #N/A | M12: =IF(VLOOKUP(G12,'Bereketli Satış'!J:AK,30,0)="","",VLOOKUP(G12,'Bereketli Satış'!J:AK,30,0)) -> #N/A | P12: =IF(VLOOKUP(G12,'Bereketli Satış'!J:AK,32,0)="","",VLOOKUP(G12,'Bereketli Satış'!J:AK,32,0)) -> #N/A
A13: BALIKESİR | B13: SUSURLUK | C13: REŞADİYE | D13: 740.38 | E13: 163 | F13: 3 | G13: =C13&E13&F13 -> REŞADİYE1633 | I13: =IF(VLOOKUP(G13,'Bereketli Satış'!J:AK,5,0)="","",VLOOKUP(G13,'Bereketli Satış'!J:AK,5,0)) -> #N/A | J13: =IF(VLOOKUP(G13,'Bereketli Satış'!J:AK,28,0)="","",VLOOKUP(G13,'Bereketli Satış'!J:AK,28,0)) -> #N/A | M13: =IF(VLOOKUP(G13,'Bereketli Satış'!J:AK,30,0)="","",VLOOKUP(G13,'Bereketli Satış'!J:AK,30,0)) -> #N/A | P13: =IF(VLOOKUP(G13,'Bereketli Satış'!J:AK,32,0)="","",VLOOKUP(G13,'Bereketli Satış'!J:AK,32,0)) -> #N/A
... A85: BALIKESİR | B85: SUSURLUK | C85: REŞADİYE | D85: 273.05 | E85: 158 | F85: 10 | G85: =C85&E85&F85 -> REŞADİYE15810 | I85: =IF(VLOOKUP(G85,'Bereketli Satış'!J:AK,5,0)="","",VLOOKUP(G85,'Bereketli Satış'!J:AK,5,0)) -> #N/A | J85: =IF(VLOOKUP(G85,'Bereketli Satış'!J:AK,28,0)="","",VLOOKUP(G85,'Bereketli Satış'!J:AK,28,0)) -> #N/A | M85: =IF(VLOOKUP(G85,'Bereketli Satış'!J:AK,30,0)="","",VLOOKUP(G85,'Bereketli Satış'!J:AK,30,0)) -> #N/A | P85: =IF(VLOOKUP(G85,'Bereketli Satış'!J:AK,32,0)="","",VLOOKUP(G85,'Bereketli Satış'!J:AK,32,0)) -> #N/A
A86: BALIKESİR | B86: DURSUNBEY | C86: DELİCE | D86: 307.74 | E86: 670 | F86: 4 | G86: =C86&E86&F86 -> DELİCE6704 | H86: 132224608 | I86: =IF(VLOOKUP(G86,'Bereketli Satış'!J:AK,5,0)="","",VLOOKUP(G86,'Bereketli Satış'!J:AK,5,0)) -> #N/A | J86: =IF(VLOOKUP(G86,'Bereketli Satış'!J:AK,28,0)="","",VLOOKUP(G86,'Bereketli Satış'!J:AK,28,0)) -> #N/A | L86: 46477 | M86: =IF(VLOOKUP(G86,'Bereketli Satış'!J:AK,30,0)="","",VLOOKUP(G86,'Bereketli Satış'!J:AK,30,0)) -> #N/A | P86: =IF(VLOOKUP(G86,'Bereketli Satış'!J:AK,32,0)="","",VLOOKUP(G86,'Bereketli Satış'!J:AK,32,0)) -> #N/A
A87: BALIKESİR | B87: SINDIRGI | C87: İBİLLER | D87: 305 | E87: 111 | F87: 14 | G87: =C87&E87&F87 -> İBİLLER11114 | I87: =IF(VLOOKUP(G87,'Bereketli Satış'!J:AK,5,0)="","",VLOOKUP(G87,'Bereketli Satış'!J:AK,5,0)) -> #N/A | J87: =IF(VLOOKUP(G87,'Bereketli Satış'!J:AK,28,0)="","",VLOOKUP(G87,'Bereketli Satış'!J:AK,28,0)) -> #N/A | M87: =IF(VLOOKUP(G87,'Bereketli Satış'!J:AK,30,0)="","",VLOOKUP(G87,'Bereketli Satış'!J:AK,30,0)) -> #N/A | P87: =IF(VLOOKUP(G87,'Bereketli Satış'!J:AK,32,0)="","",VLOOKUP(G87,'Bereketli Satış'!J:AK,32,0)) -> #N/A
A88: BALIKESİR | B88: SINDIRGI | C88: İBİLLER | D88: 305 | E88: 111 | F88: 15 | G88: =C88&E88&F88 -> İBİLLER11115 | I88: =IF(VLOOKUP(G88,'Bereketli Satış'!J:AK,5,0)="","",VLOOKUP(G88,'Bereketli Satış'!J:AK,5,0)) -> #N/A | J88: =IF(VLOOKUP(G88,'Bereketli Satış'!J:AK,28,0)="","",VLOOKUP(G88,'Bereketli Satış'!J:AK,28,0)) -> #N/A | M88: =IF(VLOOKUP(G88,'Bereketli Satış'!J:AK,30,0)="","",VLOOKUP(G88,'Bereketli Satış'!J:AK,30,0)) -> #N/A | P88: =IF(VLOOKUP(G88,'Bereketli Satış'!J:AK,32,0)="","",VLOOKUP(G88,'Bereketli Satış'!J:AK,32,0)) -> #N/A
A89: BALIKESİR | B89: SINDIRGI | C89: İBİLLER | D89: 305 | E89: 111 | F89: 24 | G89: =C89&E89&F89 -> İBİLLER11124 | I89: =IF(VLOOKUP(G89,'Bereketli Satış'!J:AK,5,0)="","",VLOOKUP(G89,'Bereketli Satış'!J:AK,5,0)) -> #N/A | J89: =IF(VLOOKUP(G89,'Bereketli Satış'!J:AK,28,0)="","",VLOOKUP(G89,'Bereketli Satış'!J:AK,28,0)) -> #N/A | M89: =IF(VLOOKUP(G89,'Bereketli Satış'!J:AK,30,0)="","",VLOOKUP(G89,'Bereketli Satış'!J:AK,30,0)) -> #N/A | P89: =IF(VLOOKUP(G89,'Bereketli Satış'!J:AK,32,0)="","",VLOOKUP(G89,'Bereketli Satış'!J:AK,32,0)) -> #N/A
A90: BALIKESİR | B90: SINDIRGI | C90: İBİLLER | D90: 305 | E90: 111 | F90: 25 | G90: =C90&E90&F90 -> İBİLLER11125 | I90: =IF(VLOOKUP(G90,'Bereketli Satış'!J:AK,5,0)="","",VLOOKUP(G90,'Bereketli Satış'!J:AK,5,0)) -> #N/A | J90: =IF(VLOOKUP(G90,'Bereketli Satış'!J:AK,28,0)="","",VLOOKUP(G90,'Bereketli Satış'!J:AK,28,0)) -> #N/A | M90: =IF(VLOOKUP(G90,'Bereketli Satış'!J:AK,30,0)="","",VLOOKUP(G90,'Bereketli Satış'!J:AK,30,0)) -> #N/A | P90: =IF(VLOOKUP(G90,'Bereketli Satış'!J:AK,32,0)="","",VLOOKUP(G90,'Bereketli Satış'!J:AK,32,0)) -> #N/A
A91: BALIKESİR | B91: SINDIRGI | C91: İBİLLER | D91: 309.19 | E91: 116 | F91: 22 | G91: =C91&E91&F91 -> İBİLLER11622 | I91: =IF(VLOOKUP(G91,'Bereketli Satış'!J:AK,5,0)="","",VLOOKUP(G91,'Bereketli Satış'!J:AK,5,0)) -> #N/A | J91: =IF(VLOOKUP(G91,'Bereketli Satış'!J:AK,28,0)="","",VLOOKUP(G91,'Bereketli Satış'!J:AK,28,0)) -> #N/A | M91: =IF(VLOOKUP(G91,'Bereketli Satış'!J:AK,30,0)="","",VLOOKUP(G91,'Bereketli Satış'!J:AK,30,0)) -> #N/A | P91: =IF(VLOOKUP(G91,'Bereketli Satış'!J:AK,32,0)="","",VLOOKUP(G91,'Bereketli Satış'!J:AK,32,0)) -> #N/A
A92: BALIKESİR | B92: SINDIRGI | C92: İBİLLER | D92: 310.06 | E92: 119 | F92: 13 | G92: =C92&E92&F92 -> İBİLLER11913 | I92: =IF(VLOOKUP(G92,'Bereketli Satış'!J:AK,5,0)="","",VLOOKUP(G92,'Bereketli Satış'!J:AK,5,0)) -> #N/A | J92: =IF(VLOOKUP(G92,'Bereketli Satış'!J:AK,28,0)="","",VLOOKUP(G92,'Bereketli Satış'!J:AK,28,0)) -> #N/A | M92: =IF(VLOOKUP(G92,'Bereketli Satış'!J:AK,30,0)="","",VLOOKUP(G92,'Bereketli Satış'!J:AK,30,0)) -> #N/A | P92: =IF(VLOOKUP(G92,'Bereketli Satış'!J:AK,32,0)="","",VLOOKUP(G92,'Bereketli Satış'!J:AK,32,0)) -> #N/A
A93: BALIKESİR | B93: SINDIRGI | C93: İBİLLER | D93: 310.07 | E93: 119 | F93: 14 | G93: =C93&E93&F93 -> İBİLLER11914 | I93: =IF(VLOOKUP(G93,'Bereketli Satış'!J:AK,5,0)="","",VLOOKUP(G93,'Bereketli Satış'!J:AK,5,0)) -> #N/A | J93: =IF(VLOOKUP(G93,'Bereketli Satış'!J:AK,28,0)="","",VLOOKUP(G93,'Bereketli Satış'!J:AK,28,0)) -> #N/A | M93: =IF(VLOOKUP(G93,'Bereketli Satış'!J:AK,30,0)="","",VLOOKUP(G93,'Bereketli Satış'!J:AK,30,0)) -> #N/A | P93: =IF(VLOOKUP(G93,'Bereketli Satış'!J:AK,32,0)="","",VLOOKUP(G93,'Bereketli Satış'!J:AK,32,0)) -> #N/A
A94: BALIKESİR | B94: SINDIRGI | C94: İBİLLER | D94: 313.92 | E94: 111 | F94: 13 | G94: =C94&E94&F94 -> İBİLLER11113 | I94: =IF(VLOOKUP(G94,'Bereketli Satış'!J:AK,5,0)="","",VLOOKUP(G94,'Bereketli Satış'!J:AK,5,0)) -> #N/A | J94: =IF(VLOOKUP(G94,'Bereketli Satış'!J:AK,28,0)="","",VLOOKUP(G94,'Bereketli Satış'!J:AK,28,0)) -> #N/A | M94: =IF(VLOOKUP(G94,'Bereketli Satış'!J:AK,30,0)="","",VLOOKUP(G94,'Bereketli Satış'!J:AK,30,0)) -> #N/A | P94: =IF(VLOOKUP(G94,'Bereketli Satış'!J:AK,32,0)="","",VLOOKUP(G94,'Bereketli Satış'!J:AK,32,0)) -> #N/A
A95: BALIKESİR | B95: SUSURLUK | C95: REŞADİYE | D95: 326.78 | E95: 158 | F95: 15 | G95: =C95&E95&F95 -> REŞADİYE15815 | I95: =IF(VLOOKUP(G95,'Bereketli Satış'!J:AK,5,0)="","",VLOOKUP(G95,'Bereketli Satış'!J:AK,5,0)) -> #N/A | J95: =IF(VLOOKUP(G95,'Bereketli Satış'!J:AK,28,0)="","",VLOOKUP(G95,'Bereketli Satış'!J:AK,28,0)) -> #N/A | M95: =IF(VLOOKUP(G95,'Bereketli Satış'!J:AK,30,0)="","",VLOOKUP(G95,'Bereketli Satış'!J:AK,30,0)) -> #N/A | P95: =IF(VLOOKUP(G95,'Bereketli Satış'!J:AK,32,0)="","",VLOOKUP(G95,'Bereketli Satış'!J:AK,32,0)) -> #N/A
A96: BALIKESİR | B96: SINDIRGI | C96: İBİLLER | D96: 320.67 | E96: 119 | F96: 22 | G96: =C96&E96&F96 -> İBİLLER11922 | I96: =IF(VLOOKUP(G96,'Bereketli Satış'!J:AK,5,0)="","",VLOOKUP(G96,'Bereketli Satış'!J:AK,5,0)) -> #N/A | J96: =IF(VLOOKUP(G96,'Bereketli Satış'!J:AK,28,0)="","",VLOOKUP(G96,'Bereketli Satış'!J:AK,28,0)) -> #N/A | M96: =IF(VLOOKUP(G96,'Bereketli Satış'!J:AK,30,0)="","",VLOOKUP(G96,'Bereketli Satış'!J:AK,30,0)) -> #N/A | P96: =IF(VLOOKUP(G96,'Bereketli Satış'!J:AK,32,0)="","",VLOOKUP(G96,'Bereketli Satış'!J:AK,32,0)) -> #N/A
A97: ANKARA | B97: GÜDÜL | C97: GÜNEYCE | D97: 400 | E97: 911 | F97: 19 | G97: =C97&E97&F97 -> GÜNEYCE91119 | I97: =IF(VLOOKUP(G97,'Bereketli Satış'!J:AK,5,0)="","",VLOOKUP(G97,'Bereketli Satış'!J:AK,5,0)) -> #N/A | J97: =IF(VLOOKUP(G97,'Bereketli Satış'!J:AK,28,0)="","",VLOOKUP(G97,'Bereketli Satış'!J:AK,28,0)) -> #N/A | M97: =IF(VLOOKUP(G97,'Bereketli Satış'!J:AK,30,0)="","",VLOOKUP(G97,'Bereketli Satış'!J:AK,30,0)) -> #N/A | P97: =IF(VLOOKUP(G97,'Bereketli Satış'!J:AK,32,0)="","",VLOOKUP(G97,'Bereketli Satış'!J:AK,32,0)) -> #N/A
A98: BALIKESİR | B98: SINDIRGI | C98: İBİLLER | D98: 340.67 | E98: 119 | F98: 20 | G98: =C98&E98&F98 -> İBİLLER11920 | I98: =IF(VLOOKUP(G98,'Bereketli Satış'!J:AK,5,0)="","",VLOOKUP(G98,'Bereketli Satış'!J:AK,5,0)) -> #N/A | J98: =IF(VLOOKUP(G98,'Bereketli Satış'!J:AK,28,0)="","",VLOOKUP(G98,'Bereketli Satış'!J:AK,28,0)) -> #N/A | M98: =IF(VLOOKUP(G98,'Bereketli Satış'!J:AK,30,0)="","",VLOOKUP(G98,'Bereketli Satış'!J:AK,30,0)) -> #N/A | P98: =IF(VLOOKUP(G98,'Bereketli Satış'!J:AK,32,0)="","",VLOOKUP(G98,'Bereketli Satış'!J:AK,32,0)) -> #N/A
... A123: BALIKESİR | B123: SUSURLUK | C123: REŞADİYE | D123: 335.81 | E123: 168 | F123: 10 | G123: =C123&E123&F123 -> REŞADİYE16810 | I123: =IF(VLOOKUP(G123,'Bereketli Satış'!J:AK,5,0)="","",VLOOKUP(G123,'Bereketli Satış'!J:AK,5,0)) -> #N/A | J123: =IF(VLOOKUP(G123,'Bereketli Satış'!J:AK,28,0)="","",VLOOKUP(G123,'Bereketli Satış'!J:AK,28,0)) -> #N/A | M123: =IF(VLOOKUP(G123,'Bereketli Satış'!J:AK,30,0)="","",VLOOKUP(G123,'Bereketli Satış'!J:AK,30,0)) -> #N/A | P123: =IF(VLOOKUP(G123,'Bereketli Satış'!J:AK,32,0)="","",VLOOKUP(G123,'Bereketli Satış'!J:AK,32,0)) -> #N/A
A124: BALIKESİR | B124: SUSURLUK | C124: REŞADİYE | D124: 337.9 | E124: 167 | F124: 9 | G124: =C124&E124&F124 -> REŞADİYE1679 | H124: 131236862 | I124: =IF(VLOOKUP(G124,'Bereketli Satış'!J:AK,5,0)="","",VLOOKUP(G124,'Bereketli Satış'!J:AK,5,0)) -> #N/A | J124: =IF(VLOOKUP(G124,'Bereketli Satış'!J:AK,28,0)="","",VLOOKUP(G124,'Bereketli Satış'!J:AK,28,0)) -> #N/A | M124: CEM ANIZ | O124: 46452 | P124: =IF(VLOOKUP(G124,'Bereketli Satış'!J:AK,32,0)="","",VLOOKUP(G124,'Bereketli Satış'!J:AK,32,0)) -> #N/A
A125: BALIKESİR | B125: SUSURLUK | C125: REŞADİYE | D125: 337.9 | E125: 167 | F125: 10 | G125: =C125&E125&F125 -> REŞADİYE16710 | H125: 131236863 | I125: =IF(VLOOKUP(G125,'Bereketli Satış'!J:AK,5,0)="","",VLOOKUP(G125,'Bereketli Satış'!J:AK,5,0)) -> #N/A | J125: =IF(VLOOKUP(G125,'Bereketli Satış'!J:AK,28,0)="","",VLOOKUP(G125,'Bereketli Satış'!J:AK,28,0)) -> #N/A | M125: CEM ANIZ | O125: 46452 | P125: =IF(VLOOKUP(G125,'Bereketli Satış'!J:AK,32,0)="","",VLOOKUP(G125,'Bereketli Satış'!J:AK,32,0)) -> #N/A
A126: BALIKESİR | B126: DURSUNBEY | C126: DELİCE | D126: 361.8 | E126: 670 | F126: 3 | G126: =C126&E126&F126 -> DELİCE6703 | H126: 132224607 | I126: =IF(VLOOKUP(G126,'Bereketli Satış'!J:AK,5,0)="","",VLOOKUP(G126,'Bereketli Satış'!J:AK,5,0)) -> #N/A | J126: =IF(VLOOKUP(G126,'Bereketli Satış'!J:AK,28,0)="","",VLOOKUP(G126,'Bereketli Satış'!J:AK,28,0)) -> #N/A | L126: 46477 | M126: =IF(VLOOKUP(G126,'Bereketli Satış'!J:AK,30,0)="","",VLOOKUP(G126,'Bereketli Satış'!J:AK,30,0)) -> #N/A | P126: =IF(VLOOKUP(G126,'Bereketli Satış'!J:AK,32,0)="","",VLOOKUP(G126,'Bereketli Satış'!J:AK,32,0)) -> #N/A
A127: BALIKESİR | B127: SUSURLUK | C127: REŞADİYE | D127: 341.92 | E127: 166 | F127: 10 | G127: =C127&E127&F127 -> REŞADİYE16610 | I127: =IF(VLOOKUP(G127,'Bereketli Satış'!J:AK,5,0)="","",VLOOKUP(G127,'Bereketli Satış'!J:AK,5,0)) -> #N/A | J127: =IF(VLOOKUP(G127,'Bereketli Satış'!J:AK,28,0)="","",VLOOKUP(G127,'Bereketli Satış'!J:AK,28,0)) -> #N/A | M127: =IF(VLOOKUP(G127,'Bereketli Satış'!J:AK,30,0)="","",VLOOKUP(G127,'Bereketli Satış'!J:AK,30,0)) -> #N/A | P127: =IF(VLOOKUP(G127,'Bereketli Satış'!J:AK,32,0)="","",VLOOKUP(G127,'Bereketli Satış'!J:AK,32,0)) -> #N/A
A128: BALIKESİR | B128: SUSURLUK | C128: REŞADİYE | D128: 341.92 | E128: 166 | F128: 9 | G128: =C128&E128&F128 -> REŞADİYE1669 | I128: =IF(VLOOKUP(G128,'Bereketli Satış'!J:AK,5,0)="","",VLOOKUP(G128,'Bereketli Satış'!J:AK,5,0)) -> #N/A | J128: =IF(VLOOKUP(G128,'Bereketli Satış'!J:AK,28,0)="","",VLOOKUP(G128,'Bereketli Satış'!J:AK,28,0)) -> #N/A | M128: =IF(VLOOKUP(G128,'Bereketli Satış'!J:AK,30,0)="","",VLOOKUP(G128,'Bereketli Satış'!J:AK,30,0)) -> #N/A | P128: =IF(VLOOKUP(G128,'Bereketli Satış'!J:AK,32,0)="","",VLOOKUP(G128,'Bereketli Satış'!J:AK,32,0)) -> #N/A
A129: BALIKESİR | B129: SINDIRGI | C129: KINIK | D129: 310.9 | E129: 315 | F129: 13 | G129: =C129&E129&F129 -> KINIK31513 | I129: =IF(VLOOKUP(G129,'Bereketli Satış'!J:AK,5,0)="","",VLOOKUP(G129,'Bereketli Satış'!J:AK,5,0)) -> #N/A | J129: =IF(VLOOKUP(G129,'Bereketli Satış'!J:AK,28,0)="","",VLOOKUP(G129,'Bereketli Satış'!J:AK,28,0)) -> #N/A | M129: =IF(VLOOKUP(G129,'Bereketli Satış'!J:AK,30,0)="","",VLOOKUP(G129,'Bereketli Satış'!J:AK,30,0)) -> #N/A | P129: =IF(VLOOKUP(G129,'Bereketli Satış'!J:AK,32,0)="","",VLOOKUP(G129,'Bereketli Satış'!J:AK,32,0)) -> #N/A
A130: BALIKESİR | B130: KARESİ | C130: KIRMIZILAR | D130: 433.54 | E130: 180 | F130: 13 | G130: =C130&E130&F130 -> KIRMIZILAR18013 | I130: =IF(VLOOKUP(G130,'Bereketli Satış'!J:AK,5,0)="","",VLOOKUP(G130,'Bereketli Satış'!J:AK,5,0)) -> #N/A | J130: =IF(VLOOKUP(G130,'Bereketli Satış'!J:AK,28,0)="","",VLOOKUP(G130,'Bereketli Satış'!J:AK,28,0)) -> #N/A | M130: =IF(VLOOKUP(G130,'Bereketli Satış'!J:AK,30,0)="","",VLOOKUP(G130,'Bereketli Satış'!J:AK,30,0)) -> #N/A | P130: =IF(VLOOKUP(G130,'Bereketli Satış'!J:AK,32,0)="","",VLOOKUP(G130,'Bereketli Satış'!J:AK,32,0)) -> #N/A
A131: BALIKESİR | B131: SUSURLUK | C131: REŞADİYE | D131: 346.88 | E131: 170 | F131: 11 | G131: =C131&E131&F131 -> REŞADİYE17011 | I131: =IF(VLOOKUP(G131,'Bereketli Satış'!J:AK,5,0)="","",VLOOKUP(G131,'Bereketli Satış'!J:AK,5,0)) -> #N/A | J131: =IF(VLOOKUP(G131,'Bereketli Satış'!J:AK,28,0)="","",VLOOKUP(G131,'Bereketli Satış'!J:AK,28,0)) -> #N/A | M131: =IF(VLOOKUP(G131,'Bereketli Satış'!J:AK,30,0)="","",VLOOKUP(G131,'Bereketli Satış'!J:AK,30,0)) -> #N/A | P131: =IF(VLOOKUP(G131,'Bereketli Satış'!J:AK,32,0)="","",VLOOKUP(G131,'Bereketli Satış'!J:AK,32,0)) -> #N/A
A132: BALIKESİR | B132: SUSURLUK | C132: REŞADİYE | D132: 348.76 | E132: 170 | F132: 12 | G132: =C132&E132&F132 -> REŞADİYE17012 | I132: =IF(VLOOKUP(G132,'Bereketli Satış'!J:AK,5,0)="","",VLOOKUP(G132,'Bereketli Satış'!J:AK,5,0)) -> #N/A | J132: =IF(VLOOKUP(G132,'Bereketli Satış'!J:AK,28,0)="","",VLOOKUP(G132,'Bereketli Satış'!J:AK,28,0)) -> #N/A | M132: =IF(VLOOKUP(G132,'Bereketli Satış'!J:AK,30,0)="","",VLOOKUP(G132,'Bereketli Satış'!J:AK,30,0)) -> #N/A | P132: =IF(VLOOKUP(G132,'Bereketli Satış'!J:AK,32,0)="","",VLOOKUP(G132,'Bereketli Satış'!J:AK,32,0)) -> #N/A
A133: MANİSA | B133: ALAŞEHİR | C133: KİLLİK | D133: 529 | E133: 214 | F133: 10 | G133: =C133&E133&F133 -> KİLLİK21410 | I133: =IF(VLOOKUP(G133,'Bereketli Satış'!J:AK,5,0)="","",VLOOKUP(G133,'Bereketli Satış'!J:AK,5,0)) -> #N/A | J133: =IF(VLOOKUP(G133,'Bereketli Satış'!J:AK,28,0)="","",VLOOKUP(G133,'Bereketli Satış'!J:AK,28,0)) -> #N/A | M133: =IF(VLOOKUP(G133,'Bereketli Satış'!J:AK,30,0)="","",VLOOKUP(G133,'Bereketli Satış'!J:AK,30,0)) -> #N/A | P133: =IF(VLOOKUP(G133,'Bereketli Satış'!J:AK,32,0)="","",VLOOKUP(G133,'Bereketli Satış'!J:AK,32,0)) -> #N/A
A134: BALIKESİR | B134: DURSUNBEY | C134: DELİCE | D134: 390.18 | E134: 670 | F134: 2 | G134: =C134&E134&F134 -> DELİCE6702 | I134: =IF(VLOOKUP(G134,'Bereketli Satış'!J:AK,5,0)="","",VLOOKUP(G134,'Bereketli Satış'!J:AK,5,0)) -> #N/A | J134: =IF(VLOOKUP(G134,'Bereketli Satış'!J:AK,28,0)="","",VLOOKUP(G134,'Bereketli Satış'!J:AK,28,0)) -> #N/A | M134: =IF(VLOOKUP(G134,'Bereketli Satış'!J:AK,30,0)="","",VLOOKUP(G134,'Bereketli Satış'!J:AK,30,0)) -> #N/A | P134: =IF(VLOOKUP(G134,'Bereketli Satış'!J:AK,32,0)="","",VLOOKUP(G134,'Bereketli Satış'!J:AK,32,0)) -> #N/A
A135: BALIKESİR | B135: KARESİ | C135: KUVAYİ MİLLİYE | D135: 321.12 | E135: 14236 | F135: 20 | G135: =C135&E135&F135 -> KUVAYİ MİLLİYE1423620 | I135: =IF(VLOOKUP(G135,'Bereketli Satış'!J:AK,5,0)="","",VLOOKUP(G135,'Bereketli Satış'!J:AK,5,0)) -> #N/A | J135: =IF(VLOOKUP(G135,'Bereketli Satış'!J:AK,28,0)="","",VLOOKUP(G135,'Bereketli Satış'!J:AK,28,0)) -> #N/A | M135: =IF(VLOOKUP(G135,'Bereketli Satış'!J:AK,30,0)="","",VLOOKUP(G135,'Bereketli Satış'!J:AK,30,0)) -> #N/A | P135: =IF(VLOOKUP(G135,'Bereketli Satış'!J:AK,32,0)="","",VLOOKUP(G135,'Bereketli Satış'!J:AK,32,0)) -> #N/A
...

Sheet İbiller satış
A1: İL | B1: İlçe | C1: MAHALLE | D1: Alan | E1: ADA | F1: PARSEL | G1: Nitelik | H1: M2 FİYATI | I1: İLAN Fiyatı | J1: PEŞİN İSKONTOLU M2 FİYATI | K1: Peşin İskontolu Fiyat | L1: 12 Ay Taksitli M2 Fiyat | M1: 12 Ay Taksitli Fiyat | N1: 12 ay taksitli peşinat | O1: 12 ay taksit tutarı | P1: 24 ay taksitli M2 fiyat | Q1: 24 ay taksitli fiyat | R1: 24 ay taksitli peşinat | S1: 24 ay taksit tutarı
A2: BALIKESİR | B2: SINDIRGI | C2: İBİLLER | D2: 390.18 | E2: 122 | F2: 37 | G2: ARSA | H2: 2500 | I2: 980000 | J2: 1750 | K2: =ROUND(J2*D2,-4) -> 680000 | L2: =1.1*J2 -> 1925 | M2: =ROUND(L2*D2,-4) -> 750000 | N2: =M2/2 -> 375000 | O2: =N2/12 -> 31250 | P2: =L2*1.1 -> 2117.5 | Q2: =ROUND(P2*D2,-4) -> 830000 | R2: =Q2/2 -> 415000 | S2: =R2/24 -> 17291.667
A3: BALIKESİR | B3: SINDIRGI | C3: İBİLLER | D3: 390.26 | E3: 122 | F3: 38 | G3: ARSA | H3: 2500 | I3: 980000 | J3: 1750 | K3: =ROUND(J3*D3,-4) -> 680000 | L3: =1.1*J3 -> 1925 | M3: =ROUND(L3*D3,-4) -> 750000 | N3: =M3/2 -> 375000 | O3: =N3/12 -> 31250 | P3: =L3*1.1 -> 2117.5 | Q3: =ROUND(P3*D3,-4) -> 830000 | R3: =Q3/2 -> 415000 | S3: =R3/24 -> 17291.667
A4: BALIKESİR | B4: SINDIRGI | C4: İBİLLER | D4: 391.1 | E4: 122 | F4: 39 | G4: ARSA | H4: 2500 | I4: 980000 | J4: 1750 | K4: =ROUND(J4*D4,-4) -> 680000 | L4: =1.1*J4 -> 1925 | M4: =ROUND(L4*D4,-4) -> 750000 | N4: =M4/2 -> 375000 | O4: =N4/12 -> 31250 | P4: =L4*1.1 -> 2117.5 | Q4: =ROUND(P4*D4,-4) -> 830000 | R4: =Q4/2 -> 415000 | S4: =R4/24 -> 17291.667
A5: BALIKESİR | B5: SINDIRGI | C5: İBİLLER | D5: 394.87 | E5: 118 | F5: 17 | G5: ARSA | H5: 2500 | I5: 990000 | J5: 1750 | K5: =ROUND(J5*D5,-4) -> 690000 | L5: =1.1*J5 -> 1925 | M5: =ROUND(L5*D5,-4) -> 760000 | N5: =M5/2 -> 380000 | O5: =N5/12 -> 31666.667 | P5: =L5*1.1 -> 2117.5 | Q5: =ROUND(P5*D5,-4) -> 840000 | R5: =Q5/2 -> 420000 | S5: =R5/24 -> 17500
A6: BALIKESİR | B6: SINDIRGI | C6: İBİLLER | D6: 396.54 | E6: 122 | F6: 17 | G6: ARSA | H6: 2500 | I6: 990000 | J6: 1750 | K6: =ROUND(J6*D6,-4) -> 690000 | L6: =1.1*J6 -> 1925 | M6: =ROUND(L6*D6,-4) -> 760000 | N6: =M6/2 -> 380000 | O6: =N6/12 -> 31666.667 | P6: =L6*1.1 -> 2117.5 | Q6: =ROUND(P6*D6,-4) -> 840000 | R6: =Q6/2 -> 420000 | S6: =R6/24 -> 17500
A7: BALIKESİR | B7: SINDIRGI | C7: İBİLLER | D7: 396.65 | E7: 122 | F7: 18 | G7: ARSA | H7: 2500 | I7: 990000 | J7: 1750 | K7: =ROUND(J7*D7,-4) -> 690000 | L7: =1.1*J7 -> 1925 | M7: =ROUND(L7*D7,-4) -> 760000 | N7: =M7/2 -> 380000 | O7: =N7/12 -> 31666.667 | P7: =L7*1.1 -> 2117.5 | Q7: =ROUND(P7*D7,-4) -> 840000 | R7: =Q7/2 -> 420000 | S7: =R7/24 -> 17500
A8: BALIKESİR | B8: SINDIRGI | C8: İBİLLER | D8: 413.58 | E8: 122 | F8: 28 | G8: ARSA | H8: 2500 | I8: 1030000 | J8: 1750 | K8: =ROUND(J8*D8,-4) -> 720000 | L8: =1.1*J8 -> 1925 | M8: =ROUND(L8*D8,-4) -> 800000 | N8: =M8/2 -> 400000 | O8: =N8/12 -> 33333.333 | P8: =L8*1.1 -> 2117.5 | Q8: =ROUND(P8*D8,-4) -> 880000 | R8: =Q8/2 -> 440000 | S8: =R8/24 -> 18333.333
A9: BALIKESİR | B9: SINDIRGI | C9: İBİLLER | D9: 417.69 | E9: 122 | F9: 16 | G9: ARSA | H9: 2500 | I9: 1040000 | J9: 1750 | K9: =ROUND(J9*D9,-4) -> 730000 | L9: =1.1*J9 -> 1925 | M9: =ROUND(L9*D9,-4) -> 800000 | N9: =M9/2 -> 400000 | O9: =N9/12 -> 33333.333 | P9: =L9*1.1 -> 2117.5 | Q9: =ROUND(P9*D9,-4) -> 880000 | R9: =Q9/2 -> 440000 | S9: =R9/24 -> 18333.333
A10: BALIKESİR | B10: SINDIRGI | C10: İBİLLER | D10: 423.76 | E10: 121 | F10: 12 | G10: ARSA | H10: 2500 | I10: 1060000 | J10: 1750 | K10: =ROUND(J10*D10,-4) -> 740000 | L10: =1.1*J10 -> 1925 | M10: =ROUND(L10*D10,-4) -> 820000 | N10: =M10/2 -> 410000 | O10: =N10/12 -> 34166.667 | P10: =L10*1.1 -> 2117.5 | Q10: =ROUND(P10*D10,-4) -> 900000 | R10: =Q10/2 -> 450000 | S10: =R10/24 -> 18750
A11: BALIKESİR | B11: SINDIRGI | C11: İBİLLER | D11: 454.13 | E11: 117 | F11: 20 | G11: ARSA | H11: 2500 | I11: 1140000 | J11: 1750 | K11: =ROUND(J11*D11,-4) -> 790000 | L11: =1.1*J11 -> 1925 | M11: =ROUND(L11*D11,-4) -> 870000 | N11: =M11/2 -> 435000 | O11: =N11/12 -> 36250 | P11: =L11*1.1 -> 2117.5 | Q11: =ROUND(P11*D11,-4) -> 960000 | R11: =Q11/2 -> 480000 | S11: =R11/24 -> 20000
A12: BALIKESİR | B12: SINDIRGI | C12: İBİLLER | D12: 460 | E12: 118 | F12: 20 | G12: ARSA | H12: 2500 | I12: 1150000 | J12: 1750 | K12: =ROUND(J12*D12,-4) -> 810000 | L12: =1.1*J12 -> 1925 | M12: =ROUND(L12*D12,-4) -> 890000 | N12: =M12/2 -> 445000 | O12: =N12/12 -> 37083.333 | P12: =L12*1.1 -> 2117.5 | Q12: =ROUND(P12*D12,-4) -> 970000 | R12: =Q12/2 -> 485000 | S12: =R12/24 -> 20208.333
A13: BALIKESİR | B13: SINDIRGI | C13: İBİLLER | D13: 460 | E13: 118 | F13: 21 | G13: ARSA | H13: 2500 | I13: 1150000 | J13: 1750 | K13: =ROUND(J13*D13,-4) -> 810000 | L13: =1.1*J13 -> 1925 | M13: =ROUND(L13*D13,-4) -> 890000 | N13: =M13/2 -> 445000 | O13: =N13/12 -> 37083.333 | P13: =L13*1.1 -> 2117.5 | Q13: =ROUND(P13*D13,-4) -> 970000 | R13: =Q13/2 -> 485000 | S13: =R13/24 -> 20208.333
A14: BALIKESİR | B14: SINDIRGI | C14: İBİLLER | D14: 460 | E14: 118 | F14: 22 | G14: ARSA | H14: 2500 | I14: 1150000 | J14: 1750 | K14: =ROUND(J14*D14,-4) -> 810000 | L14: =1.1*J14 -> 1925 | M14: =ROUND(L14*D14,-4) -> 890000 | N14: =M14/2 -> 445000 | O14: =N14/12 -> 37083.333 | P14: =L14*1.1 -> 2117.5 | Q14: =ROUND(P14*D14,-4) -> 970000 | R14: =Q14/2 -> 485000 | S14: =R14/24 -> 20208.333

Sheet Master Veri 
A1: ŞEHİRAYDIN | B1: İLÇE | C1: MAHALLE | D1: YÜZ ÖLÇÜMÜ M2 | E1: ADA | F1: PARSEL | G1: KOD | H1: HANGİ ŞİRKET? | I1: RESMİ ALIŞ FİYATI (KDV HARİÇ) | J1: RESMİ SATIŞ FİYATI
A2: BALIKESİR | B2: KARESİ | C2: TURPLU | D2: 615.05 | E2: 138 | F2: 4 | G2: =C2&E2&F2 -> TURPLU1384 | H2: BİLAL AKTAŞ | I2: 160000 | J2: 105000
A3: BALIKESİR | B3: KARESİ | C3: BÜYÜKPINAR | D3: 952.16 | E3: 135 | F3: 5 | G3: =C3&E3&F3 -> BÜYÜKPINAR1355 | H3: BİLAL AKTAŞ | I3: 70000 | J3: 80000
A4: BALIKESİR | B4: KARESİ | C4: BÜYÜKPINAR | D4: 1130.52 | E4: 135 | F4: 1 | G4: =C4&E4&F4 -> BÜYÜKPINAR1351 | H4: BİLAL AKTAŞ | I4: 75000 | J4: 80000
A5: BALIKESİR | B5: KARESİ | C5: BAKACAK | D5: 499.86 | E5: 121 | F5: 5 | G5: =C5&E5&F5 -> BAKACAK1215 | H5: BİLAL AKTAŞ | I5: 230000 | J5: 240000
A6: BALIKESİR | B6: ALTIEYLÜL | C6: SELİMİYE | D6: 561.91 | E6: 128 | F6: 2 | G6: =C6&E6&F6 -> SELİMİYE1282 | H6: BİLAL AKTAŞ | I6: 232000 | J6: 250000
A7: BALIKESİR | B7: SINDIRGI | C7: ARMUTLU | D7: 559.9 | E7: 104 | F7: 5 | G7: =C7&E7&F7 -> ARMUTLU1045 | H7: BEREKETLİ AŞ | I7: 310000 | J7: 345000
A8: BALIKESİR | B8: KARESİ | C8: BÜYÜKPINAR | D8: 984.65 | E8: 134 | F8: 6 | G8: =C8&E8&F8 -> BÜYÜKPINAR1346 | H8: BİLAL AKTAŞ | I8: 15000 | J8: 20900
A9: BALIKESİR | B9: KARESİ | C9: BÜYÜKPINAR | D9: 928.38 | E9: 134 | F9: 8 | G9: =C9&E9&F9 -> BÜYÜKPINAR1348 | H9: BİLAL AKTAŞ | I9: 15000 | J9: 25900
A10: BALIKESİR | B10: KARESİ | C10: BÜYÜKPINAR | D10: 1040.5 | E10: 134 | F10: 7 | G10: =C10&E10&F10 -> BÜYÜKPINAR1347 | H10: BİLAL AKTAŞ | I10: 15000 | J10: 25900
A11: BALIKESİR | B11: SINDIRGI | C11: DERECİKÖREN | D11: 343.53 | E11: 205 | F11: 5 | G11: =C11&E11&F11 -> DERECİKÖREN2055 | H11: BİLAL AKTAŞ | I11: 6500 | J11: 7000
A12: ÇANAKKALE | B12: BİGA | C12: ÇEŞMEALTI | D12: 490.73 | E12: 588 | F12: 4 | G12: =C12&E12&F12 -> ÇEŞMEALTI5884 | H12: BİLAL AKTAŞ | I12: 100000 | J12: 101000
A13: BALIKESİR | B13: İVRİNDİ | C13: GÖZLÜÇAYIR | D13: 528.46 | E13: 165 | F13: 60 | G13: =C13&E13&F13 -> GÖZLÜÇAYIR16560 | H13: BİLAL AKTAŞ | I13: 3435 | J13: 5000
... A37: MANİSA | B37: ŞEHZADELER | C37: TEPECİK | D37: 612.5 | E37: 102 | F37: 4 | G37: =C37&E37&F37 -> TEPECİK1024 | H37: BİLAL AKTAŞ | I37: 380000 | J37: 400000
A38: BALIKESİR | B38: SINDIRGI | C38: ARMUTLU | D38: 793.35 | E38: 102 | F38: 1 | G38: =C38&E38&F38 -> ARMUTLU1021 | H38: BEREKETLİ AŞ | I38: 445000
A39: BALIKESİR | B39: KARESİ | C39: KUVAYİ MİLLİYE | D39: 304.6 | E39: 12450 | F39: 11 | G39: =C39&E39&F39 -> KUVAYİ MİLLİYE1245011 | H39: BİLAL AKTAŞ | I39: 165000 | J39: 170000
A40: BALIKESİR | B40: SINDIRGI | C40: ARMUTLU | D40: 816 | E40: 102 | F40: 3 | G40: =C40&E40&F40 -> ARMUTLU1023 | H40: BEREKETLİ AŞ | I40: 455000 | J40: 460000
A41: BALIKESİR | B41: SINDIRGI | C41: ARMUTLU | D41: 816 | E41: 102 | F41: 4 | G41: =C41&E41&F41 -> ARMUTLU1024 | H41: BEREKETLİ AŞ | I41: 460000 | J41: 480000
A42: BALIKESİR | B42: KARESİ | C42: KUVAYİ MİLLİYE | D42: 304.52 | E42: 12450 | F42: 9 | G42: =C42&E42&F42 -> KUVAYİ MİLLİYE124509 | H42: BİLAL AKTAŞ | I42: 165000 | J42: 167000
A43: BALIKESİR | B43: KARESİ | C43: NAİPLİ | D43: 1221.58 | E43: 122 | F43: 8 | G43: =C43&E43&F43 -> NAİPLİ1228 | H43: BİLAL AKTAŞ | I43: 30000 | J43: 0
A44: BALIKESİR | B44: KARESİ | C44: BÜYÜKPINAR | D44: 785.63 | E44: 123 | F44: 6 | G44: =C44&E44&F44 -> BÜYÜKPINAR1236 | H44: BİLAL AKTAŞ | I44: 100000 | J44: 165000
A45: BALIKESİR | B45: KARESİ | C45: BÜYÜKPINAR | D45: 693.89 | E45: 123 | F45: 2 | G45: =C45&E45&F45 -> BÜYÜKPINAR1232 | H45: BİLAL AKTAŞ | I45: 50000 | J45: 55000
A46: BALIKESİR | B46: KARESİ | C46: BÜYÜKPINAR | D46: 777.22 | E46: 133 | F46: 5 | G46: =C46&E46&F46 -> BÜYÜKPINAR1335 | H46: BİLAL AKTAŞ | I46: 50000 | J46: 55000
A47: MANİSA | B47: DEMİRCİ | C47: HÜDÜK | D47: 1276.43 | E47: 169 | F47: 6 | G47: =C47&E47&F47 -> HÜDÜK1696 | H47: BİLAL AKTAŞ | I47: 18000 | J47: 0
A48: MANİSA | B48: DEMİRCİ | C48: BOYACIK | D48: 1140.36 | E48: 215 | F48: 20 | G48: =C48&E48&F48 -> BOYACIK21520 | H48: BİLAL AKTAŞ | I48: 19000 | J48: 0
A49: MANİSA | B49: DEMİRCİ | C49: KULALAR | D49: 1528.07 | E49: 128 | F49: 2 | G49: =C49&E49&F49 -> KULALAR1282 | H49: BİLAL AKTAŞ | I49: 55000 | J49: 0
A50: MANİSA | B50: DEMİRCİ | C50: MİNNETLER | D50: 2059.02 | E50: 103 | F50: 558 | G50: =C50&E50&F50 -> MİNNETLER103558 | H50: BİLAL AKTAŞ | I50: 30000 | J50: 0
... A68: BALIKESİR | B68: KARESİ | C68: BÜYÜKPINAR | D68: 614.75 | E68: 125 | F68: 5 | G68: =C68&E68&F68 -> BÜYÜKPINAR1255 | H68: BİLAL AKTAŞ | I68: 25000 | J68: 30000
A69: BALIKESİR | B69: SINDIRGI | C69: ARMUTLU | D69: 816 | E69: 102 | F69: 7 | G69: =C69&E69&F69 -> ARMUTLU1027 | H69: BEREKETLİ AŞ | I69: 460000
A70: MANİSA | B70: GÖRDES | C70: BEĞEL | D70: 302.21 | E70: 103 | F70: 6 | G70: =C70&E70&F70 -> BEĞEL1036 | H70: BİLAL AKTAŞ | I70: 20000 | J70: 22000
A71: BALIKESİR | B71: KARESİ | C71: BÜYÜKPINAR | D71: 988.72 | E71: 135 | F71: 4 | G71: =C71&E71&F71 -> BÜYÜKPINAR1354 | H71: BİLAL AKTAŞ | I71: 30000 | J71: 35000
A72: BALIKESİR | B72: KARESİ | C72: KIRMIZILAR | D72: 433.54 | E72: 180 | F72: 13 | G72: =C72&E72&F72 -> KIRMIZILAR18013 | H72: BİLAL AKTAŞ | I72: 50000 | J72: 52000
A73: BALIKESİR | B73: KARESİ | C73: KIRMIZILAR | D73: 461.08 | E73: 180 | F73: 14 | G73: =C73&E73&F73 -> KIRMIZILAR18014 | H73: BİLAL AKTAŞ | I73: 50000 | J73: 52000
A74: BALIKESİR | B74: KARESİ | C74: KUVAYİ MİLLİYE | D74: 304.48 | E74: 12450 | F74: 10 | G74: =C74&E74&F74 -> KUVAYİ MİLLİYE1245010 | H74: BİLAL AKTAŞ | I74: 165000 | J74: 170000
A75: BALIKESİR | B75: KARESİ | C75: KUVAYİ MİLLİYE | D75: 299.34 | E75: 12450 | F75: 2 | G75: =C75&E75&F75 -> KUVAYİ MİLLİYE124502 | H75: BİLAL AKTAŞ | I75: 165000
A76: BALIKESİR | B76: KARESİ | C76: KUVAYİ MİLLİYE | D76: 303.03 | E76: 12450 | F76: 3 | G76: =C76&E76&F76 -> KUVAYİ MİLLİYE124503 | H76: BİLAL AKTAŞ | I76: 165000 | J76: 170000
A77: BALIKESİR | B77: KARESİ | C77: KUVAYİ MİLLİYE | D77: 306.77 | E77: 12450 | F77: 4 | G77: =C77&E77&F77 -> KUVAYİ MİLLİYE124504 | H77: BİLAL AKTAŞ | I77: 165000 | J77: 170000
A78: BALIKESİR | B78: KARESİ | C78: KUVAYİ MİLLİYE | D78: 310.77 | E78: 12450 | F78: 5 | G78: =C78&E78&F78 -> KUVAYİ MİLLİYE124505 | H78: BİLAL AKTAŞ | I78: 165000 | J78: 170000
A79: BALIKESİR | B79: KARESİ | C79: KUVAYİ MİLLİYE | D79: 375.52 | E79: 12450 | F79: 6 | G79: =C79&E79&F79 -> KUVAYİ MİLLİYE124506 | H79: BİLAL AKTAŞ | I79: 205000 | J79: 210000
A80: İZMİR | B80: DİKİLİ | C80: İSLAMLAR | D80: 438.52 | E80: 103 | F80: 7 | G80: =C80&E80&F80 -> İSLAMLAR1037 | H80: BİLAL AKTAŞ | I80: 350000 | J80: 500000
...

Sheet Bereketli Satış
B1: STOK TÜRÜ | C1: ÖNCELİK | D1: İL | E1: İLÇE | F1: MAHALLE | G1: ALAN | H1: ADA | I1: PARSEL | J1: NİTELİK | K1: ŞİRKET | L1: DURUM | M1: DURUM 2 | N1: M2 FİYATI | O1: PEŞİN FİYAT | P1: PEŞİN İSKONTOLU FİYAT | Q1: 12 AY TAKSİTLİ M2 | R1: 12 AY TAKSİTLİ FİYAT | S1: 24 AY Taksitli M2 | T1: 24 Ay Taksitli Fiyat | U1: TAKS | V1: KAKS (EMSAL) | W1: TAŞINMAZ ID | X1: DANIŞMAN | Y1: YAYINLACAK | Z1: DOPİNG | AA1: YAYINA ALMA DURUMU | AB1: WEB | AC1: SAHİBİNDEN | AD1: HEPSİ EMLAK | AE1: MÜŞTERİ | AF1: BEYAN | AG1: EİDS YETKİ BİTİŞ | AH1: 2. Müşteri | AI1: BEYAN | AJ1: EİDS YETKİ BİTİŞ | AK1: 3. Müşteri | AL1: BEYAN | AM1: EİDS YETKİ DURUMU | AN1: ŞİRKET EİDS YETKİ BİTİŞ TARİHİ
A2: =F2&H2&I2 -> BARDAKÇI1086 | B2: DEĞİL - SATILDI | D2: MANİSA | E2: DEMİRCİ | F2: BARDAKÇI | G2: 344.75 | H2: 108 | I2: 6 | J2: ARSA | K2: BİLAL AKTAŞ | L2: SATIŞ KAPANDI | M2: SATIŞ KAPANDI | N2: 2250 | O2: =ROUND(N2*G2,-4) -> 780000 | P2: =O2*0.9 -> 702000 | Q2: - | R2: - | S2: - | T2: - | U2: 0.25 | V2: 0.5 | AB2: İLAN | AC2: 1232319721 | AD2: 136598-1554 | AE2: KORAY KIVAM | AH2: MEHMET AKKAŞ | AK2: OLCAY KUBİLAY
A3: =F3&H3&I3 -> İNKÖY48681 | B3: STOK - HAZIR | D3: KÜTAHYA | E3: MERKEZ | F3: İNKÖY | G3: 3240 | H3: 4868 | I3: 1 | J3: ARSA | K3: BEREKETLİ AŞ | L3: İLAN BEKLİYOR | M3: STOKTA | N3: 18000 | O3: =ROUND(N3*G3,-4) -> 58320000 | P3: =O3*0.9 -> 52488000
A4: =F4&H4&I4 -> BAKACAK1215 | B4: DEĞİL - SATILDI | D4: BALIKESİR | E4: KARESİ | F4: BAKACAK | G4: 499.86 | H4: 121 | I4: 5 | J4: ARSA | K4: BİLAL AKTAŞ | L4: SATIŞ KAPANDI | M4: SATIŞ KAPANDI | W4: 109806451 | AE4: GÖKHAN AYDIN
A5: =F5&H5&I5 -> BALIKLIDERE14934 | B5: DEĞİL - SATILDI | D5: BALIKESİR | E5: SUSURLUK | F5: BALIKLIDERE | G5: 638 | H5: 149 | I5: 34 | J5: ARSA | K5: BEREKETLİ AŞ | L5: SATIŞ KAPANDI | M5: SATIŞ KAPANDI | N5: 4000 | O5: =ROUND(N5*G5,-4) -> 2550000 | P5: =O5*0.9 -> 2295000 | U5: 0.4 | V5: 0.8 | AC5: 1246780393 | AE5: Hüseyin Avni Çelebi
A6: =F6&H6&I6 -> DEMİRKAPI1121 | B6: DEĞİL - SATILDI | D6: BALIKESİR | E6: SUSURLUK | F6: DEMİRKAPI | G6: 754.23 | H6: 112 | I6: 1 | J6: ARSA | K6: DORTAGE AŞ | L6: SATIŞ KAPANDI | M6: SATIŞ KAPANDI | AE6: İSMAİL ALP
A7: =F7&H7&I7 -> ARMUTLU1021 | B7: STOK - İPOTEK | C7: ÖNCELİKLİ | D7: BALIKESİR | E7: SINDIRGI | F7: ARMUTLU | G7: 793.35 | H7: 102 | I7: 1 | J7: ARSA | K7: BEREKETLİ AŞ | L7: İLANDA | M7: STOKTA/İPOTEKLİ | N7: 2250 | O7: =ROUND(N7*G7,-4) -> 1790000 | P7: =O7*0.9 -> 1611000 | Q7: =N7*1.1 -> 2475 | R7: =ROUND(Q7*G7,-4) -> 1960000 | S7: =Q7*1.1 -> 2722.5 | T7: =ROUND(S7*G7,-4) -> 2160000 | U7: 0.25 | V7: 0.5 | W7: 64213520 | AB7: İlan | AD7: 136598-1086 | AN7: 31/12/2035
A8: =F8&H8&I8 -> ILICABOĞAZI10328 | B8: DEĞİL - SATILDI | D8: BALIKESİR | E8: SUSURLUK | F8: ILICABOĞAZI | G8: 511.2 | H8: 103 | I8: 28 | J8: ARSA | K8: BEREKETLİ AŞ | L8: SATILDI | M8: SATIŞ KAPANDI | N8: 4000 | O8: =ROUND(N8*G8,-4) -> 2040000 | P8: =O8*0.9 -> 1836000 | U8: 0.4 | V8: 0.8 | W8: 134707943 | AB8: LİNK | AE8: TANER SEZER | AN8: 31/12/2035
A9: =F9&H9&I9 -> ALHAN1043 | B9: DEĞİL - SATILDI | D9: AYDIN | E9: YENİPAZAR | F9: ALHAN | G9: 407.09 | H9: 104 | I9: 3 | J9: ARSA | K9: BEREKETLİ AŞ | L9: SATIŞ KAPANDI | M9: SATILDI/2. SATIŞTA | N9: 3000 | O9: =ROUND(N9*G9,-4) -> 1220000 | P9: =O9*0.9 -> 1098000 | Q9: ? | U9: 0.2 | V9: 0.4 | W9: 126358686 | X9: HAKAN YANT | AB9: WEB | AC9: 1254034358 | AE9: ŞEYMA BEKAR | AN9: 31/12/2035
A10: =F10&H10&I10 -> GÜNEYCE91120 | B10: DEĞİL - SATILDI | D10: ANKARA | E10: GÜDÜL | F10: GÜNEYCE | G10: 400 | H10: 911 | I10: 20 | J10: ARSA | K10: BİLAL AKTAŞ | L10: SATILDI | M10: SATIŞ KAPANDI | N10: 2000 | O10: =ROUND(N10*G10,-4) -> 800000 | P10: =O10*0.9 -> 720000 | U10: 0.11 | V10: 0.35 | X10: HAKAN YANT | Z10: OK | AC10: 1250555803 | AD10: 36598-1778 | AE10: MEHMET EMİN AKTAŞ | AH10: BANU GÜLCE
A11: =F11&H11&I11 -> KAYAELİ173282 | B11: STOK - KONS - ŞAHIS | D11: BALIKESİR | E11: KEPSUT | F11: KAYAELİ | G11: 4454.48 | H11: 173 | I11: 282 | J11: TARLA | K11: BİLAL AKTAŞ | L11: İLAN BEKLİYOR | M11: SATILDI/2. SATIŞTA | N11: 112 | O11: =ROUND(N11*G11,-4) -> 500000 | P11: =O11*0.9 -> 450000 | U11: 0 | V11: 0 | W11: 109371272 | AB11: İLAN | AC11: 1220475793/ | AD11: 136598-1564 | AE11: NİSA SAKAR | AG11: 31.12.2027
A12: =F12&H12&I12 -> CAMİKEBİR31624 | B12: STOK - İPOTEK | C12: ÖNCELİKLİ | D12: AYDIN | E12: GERMENCİK | F12: CAMİKEBİR | G12: 271.36 | H12: 316 | I12: 24 | J12: ARSA | K12: BEREKETLİ AŞ | L12: SATIŞ KAPANDI | M12: STOKTA/İPOTEKLİ | N12: 4500 | O12: =ROUND(N12*G12,-4) -> 1220000 | P12: =O12*0.9 -> 1098000 | Q12: - | R12: - | S12: - | T12: - | U12: 0.4 | V12: 0.8 | W12: 68327765 | AD12: 136598-1439 | AE12: İPOTEKLİ | AN12: 31/12/2035
A13: =F13&H13&I13 -> AŞAĞIMUSALAR1704 | B13: DEĞİL - SATILDI | D13: BALIKESİR | E13: DURSUNBEY | F13: AŞAĞIMUSALAR | G13: 301.66 | H13: 170 | I13: 4 | J13: ARSA | K13: BİLAL AKTAŞ | L13: İLANDA | M13: SATIŞ KAPANDI | N13: 2250 | O13: =ROUND(N13*G13,-4) -> 680000 | P13: =O13*0.9 -> 612000 | U13: 0.4 | V13: 0.8 | W13: 133925473 | X13: HASAN UYSAL | Y13: OK | Z13: OK | AB13: İLAN YOK GİRİLECEK | AC13: 1232329009 | AD13: 136598-1511 | AE13: MERT OSKAN | AG13: 31.12.2027
A14: =F14&H14&I14 -> ÇELİKLER11669 | B14: STOK - KONS - ŞAHIS | C14: ÖNCELİKLİ | D14: BALIKESİR | E14: DURSUNBEY | F14: ÇELİKLER | G14: 870.75 | H14: 116 | I14: 69 | J14: ARSA | K14: BİLAL AKTAŞ | L14: İLANDA | M14: SATILDI/2. SATIŞTA | N14: 1280 | O14: =ROUND(N14*G14,-4) -> 1110000 | P14: =O14*0.9 -> 999000 | Q14: - | R14: - | S14: - | T14: - | U14: 0.4 | V14: 0.8 | W14: 116740568 | X14: HASAN UYSAL | Y14: OK | Z14: OK | AB14: 241 | AC14: 1226877731 | AD14: 136598-1609 | AE14: EMRE-FİLİZ TEK | AG14: 46387
A15: =F15&H15&I15 -> DELİCE25121 | B15: STOK - KONS - ŞAHIS | D15: BALIKESİR | E15: DURSUNBEY | F15: DELİCE | G15: 302.61 | H15: 251 | I15: 21 | J15: ARSA | K15: BEREKETLİ AŞ | L15: İLANDA | M15: SATILDI/2. SATIŞTA | N15: 2500 | O15: =ROUND(N15*G15,-4) -> 760000 | P15: =O15*0.9 -> 684000 | Q15: - | R15: - | S15: - | T15: - | U15: 0.4 | V15: 0.8 | X15: HAKAN YANT | Z15: OK | AB15: İLAN YOK GİRİLECEK | AC15: 250536976 | AD15: 136598-1651 | AE15: SEZEN KAYNAR ALPAN
A16: =F16&H16&I16 -> ATBURGAZI1103 | B16: STOK - HAZIR | D16: AYDIN | E16: SÖKE | F16: ATBURGAZI | G16: 300.07 | H16: 110 | I16: 3 | J16: ARSA | K16: DORTAGE AŞ | L16: REZERVE | M16: REZERVE | N16: 6000 | O16: =ROUND(N16*G16,-4) -> 1800000 | P16: =O16*0.9 -> 1620000 | Q16: =N16*1.1 -> 6600 | R16: =ROUND(Q16*G16,-4) -> 1980000 | U16: 0.4 | V16: 0.8 | X16: HAKAN YANT | AC16: 1289507920 | AD16: 45778404
A17: =F17&H17&I17 -> İSLAMLAR1012 | B17: STOK - İPOTEK | D17: İZMİR | E17: DİKİLİ | F17: İSLAMLAR | G17: 438.12 | H17: 101 | I17: 2 | J17: ARSA | K17: BEREKETLİ AŞ | L17: İLANDA | M17: STOKTA/İPOTEKLİ | N17: 16000 | O17: =ROUND(N17*G17,-4) -> 7010000 | P17: =O17*0.9 -> 6309000 | S17: - | T17: - | U17: 0.2 | V17: 0.4 | W17: 27288744 | X17: BİLAL AKTAŞ | AB17: LİNK | AC17: 1220786730 | AD17: 136598-1580 | AN17: 31/12/2035
A18: =F18&H18&I18 -> MİLİNGE0969 | B18: STOK - KONS - ŞAHIS | C18: ÖNCELİKLİ | D18: MANİSA | E18: AKHİSAR | F18: MİLİNGE | G18: 578 | H18: 0 | I18: 969 | J18: ARSA | K18: BİLAL AKTAŞ | L18: İLAN BEKLİYOR | M18: SATILDI/2. SATIŞTA | N18: 2500 | O18: =ROUND(N18*G18,-4) -> 1450000 | P18: =O18*0.9 -> 1305000 | Q18: - | R18: - | U18: 0.4 | V18: 0.5 | X18: SEMİH AYGÜN | Z18: OK | AD18: 136598-1541 | AE18: MESUT ÇINAR
A19: =F19&H19&I19 -> ERDEL2669 | B19: STOK - KONS - ŞAHIS | D19: BALIKESİR | E19: İVRİNDİ | F19: ERDEL | G19: 461.58 | H19: 266 | I19: 9 | J19: ARSA | K19: BİLAL AKTAŞ | L19: İLAN BEKLİYOR | M19: SATILDI/2. SATIŞTA | N19: 2000 | O19: =ROUND(N19*G19,-4) -> 920000 | P19: =O19*0.9 -> 828000 | Q19: - | R19: - | S19: - | T19: - | U19: 0.4 | V19: 0.8 | W19: 127961575 | AB19: İLAN | AC19: 1232427636 | AD19: 136598-1555 | AE19: MESUT MURATOĞLU | AG19: 46022
A20: =F20&H20&I20 -> AKPINAR61431 | B20: STOK - EMANET | D20: BURSA | E20: OSMANGAZİ | F20: AKPINAR | G20: 117 | H20: 6143 | I20: 1 | J20: EV | K20: BEREKETLİ AŞ | L20: İLAN BEKLİYOR | M20: STOKTA | AE20: MEHMET AKKAŞ'ın evi
A21: =F21&H21&I21 -> ÇALI597114 | B21: STOK - İPOTEK | D21: BURSA | E21: NİLÜFER | F21: ÇALI | G21: 100 | H21: 5971 | I21: 14 | J21: EV | K21: BEREKETLİ AŞ | L21: İLAN BEKLİYOR | M21: STOKTA/İPOTEKLİ
A22: =F22&H22&I22 -> BÜYÜKPINAR1401 | B22: STOK - KONS - ŞAHIS | D22: BALIKESİR | E22: KARESİ | F22: BÜYÜKPINAR | G22: 489.34 | H22: 140 | I22: 1 | J22: ARSA | K22: BEREKETLİ AŞ | L22: İLAN BEKLİYOR | M22: SATILDI/2. SATIŞTA | N22: 2500 | O22: =ROUND(N22*G22,-4) -> 1220000 | P22: =O22*0.9 -> 1098000 | Q22: - | R22: - | S22: - | T22: - | U22: 0.2 | V22: 0.4 | X22: HASAN UYSAL | AB22: İLAN | AC22: 1237631783 | AD22: 136598-1653 | AE22: DOĞAN KINIK | AG22: 46752
A23: =F23&H23&I23 -> İBİLLER12237 | B23: STOK - HAZIR | C23: ÖNCELİKLİ | D23: BALIKESİR | E23: SINDIRGI | F23: İBİLLER | G23: 390.18 | H23: 122 | I23: 37 | J23: ARSA | K23: BİLAL AKTAŞ | L23: İLANDA | M23: STOKTA | N23: 2500 | O23: =ROUND(N23*G23,-4) -> 980000 | P23: =O23*0.9 -> 882000 | Q23: =N23*1.1 -> 2750 | R23: =ROUND(Q23*G23,-4) -> 1070000 | S23: =Q23*1.1 -> 3025 | T23: =ROUND(S23*G23,-4) -> 1180000 | U23: 0.25 | V23: 0.5 | W23: 134190116 | AC23: 1237644891 | AD23: 136598-1661 | AN23: 31/12/2035
A24: =F24&H24&I24 -> ÇEŞMEALTI5884 | B24: DEĞİL - SATILDI | D24: ÇANAKKALE | E24: BİGA | F24: ÇEŞMEALTI | G24: 490.73 | H24: 588 | I24: 4 | J24: ARSA | K24: BİLAL AKTAŞ | L24: SATIŞ KAPANDI | M24: SATIŞ KAPANDI | Q24: - | R24: - | S24: - | T24: - | AB24: İLAN GİRİLMESİN | AC24: İLAN GİRİLMESİN | AE24: ÖZGE AYTEN GÜDEN | AH24: MURAT DEMİR'İN MÜŞTERİSİ seyfettin karcı
A25: =F25&H25&I25 -> DAĞYENİCE13011 | B25: STOK - KONS - ŞAHIS | D25: BURSA | E25: NİLÜFER | F25: DAĞYENİCE | G25: 6351 | H25: 130 | I25: 11 | J25: TARLA | K25: BİLAL AKTAŞ | L25: İLANDA | M25: MÜŞTERİ YERİ | N25: 7873 | O25: =ROUND(N25*G25,-4) -> 50000000 | P25: =O25*0.9 -> 45000000 | X25: BİLAL AKTAŞ | AC25: LİNK | AD25: LİNK
A26: =F26&H26&I26 -> GEDELEK765368 | B26: STOK - İPOTEK | D26: BURSA | E26: ORHANGAZİ | F26: GEDELEK | G26: 3204.35 | H26: 765 | I26: 368 | J26: TARLA | K26: BİLAL AKTAŞ | L26: SATIŞ KAPANDI | M26: STOKTA/İPOTEKLİ | N26: 5000 | O26: =ROUND(N26*G26,-4) -> 16020000 | P26: =O26*0.9 -> 14418000 | Q26: - | R26: - | S26: - | T26: - | U26: 0 | V26: 0 | W26: 89908765 | X26: BİLAL AKTAŞ | AC26: 1232388851 | AE26: BİLAL AKTAŞ | AN26: 31/12/2035
A27: =F27&H27&I27 -> DERECİKÖREN2055 | B27: DEĞİL - SATILDI | D27: BALIKESİR | E27: SINDIRGI | F27: DERECİKÖREN | G27: 343.53 | H27: 205 | I27: 5 | J27: ARSA | K27: BİLAL AKTAŞ | L27: SATIŞ KAPANDI | M27: SATIŞ KAPANDI | AB27: İLAN | AD27: 136598-999 | AE27: FATMA FAİKOĞLU
A28: =F28&H28&I28 -> HASANAĞA1834 | B28: STOK - İPOTEK | D28: BURSA | E28: NİLÜFER | F28: HASANAĞA | G28: 114 | H28: 183 | I28: 4 | J28: EV | K28: BEREKETLİ AŞ | L28: İLAN BEKLİYOR | M28: STOKTA/İPOTEKLİ
A29: =F29&H29&I29 -> İSTİKLAL22915 | B29: DEĞİL - SATILDI | D29: ÇANAKKALE | E29: ÇAN | F29: İSTİKLAL | G29: 276.64 | H29: 229 | I29: 15 | J29: ARSA | K29: BİLAL AKTAŞ | L29: SATILDI | M29: SATIŞ KAPANDI | U29: 0.4 | V29: 0.8 | AE29: EMRAH ÇAKIR
A30: =F30&H30&I30 -> KARAKÖY1071 | B30: STOK - İPOTEK | D30: BURSA | E30: YENİŞEHİR | F30: KARAKÖY | G30: 759.96 | H30: 107 | I30: 1 | J30: ARSA | K30: BEREKETLİ AŞ | L30: REZERVE | M30: STOKTA/İPOTEKLİ | N30: 8000 | O30: =ROUND(N30*G30,-4) -> 6080000 | P30: =O30*0.9 -> 5472000 | U30: 0.15 | V30: 0.3 | W30: 73164103 | AN30: 31/12/2035
A31: =F31&H31&I31 -> KAHVETEPE0816 | B31: STOK - KONS - ŞAHIS | D31: ÇANAKKALE | E31: BİGA | F31: KAHVETEPE | G31: 552 | H31: 0 | I31: 816 | J31: ARSA | K31: BEREKETLİ AŞ | L31: İLANDA | M31: SATILDI/2. SATIŞTA | N31: 3500 | O31: =ROUND(N31*G31,-4) -> 1930000 | P31: =O31*0.9 -> 1737000 | U31: 0.4 | V31: 0.8 | W31: 77313989 | X31: HAKAN YANT | AB31: WEB | AC31: 1251837434 | AE31: MEHMET FAHRİ İŞİNİBİLİR
A32: =F32&H32&I32 -> KATIRALANI1499 | B32: DEĞİL - SATILDI | D32: İZMİR | E32: DİKİLİ | F32: KATIRALANI | G32: 429.23 | H32: 149 | I32: 9 | J32: ARSA | K32: BİLAL AKTAŞ | L32: SATIŞ KAPANDI | M32: SATIŞ KAPANDI | N32: 11000 | O32: =ROUND(N32*G32,-4) -> 4720000 | P32: =O32*0.9 -> 4248000 | Q32: - | R32: - | S32: - | T32: - | U32: 0.25 | V32: 0.5 | W32: 27292578 | AC32: 1232393664 | AD32: 136598-1520 | AE32: İREM UÇAN | AH32: SEZGİN GÜLSÜN
A33: =F33&H33&I33 -> KEPEKLER0526 | B33: STOK - İPOTEK | D33: BALIKESİR | E33: SUSURLUK | F33: KEPEKLER | G33: 5050.64 | H33: 0 | I33: 526 | J33: ARSA | K33: BEREKETLİ AŞ | L33: İLAN BEKLİYOR | M33: STOKTA/İPOTEKLİ | N33: 2500 | O33: =ROUND(N33*G33,-4) -> 12630000 | P33: =O33*0.9 -> 11367000
A34: =F34&H34&I34 -> MURADİYE02615 | B34: DEĞİL - SATILDI | D34: BALIKESİR | E34: SUSURLUK | F34: MURADİYE | G34: 599 | H34: 0 | I34: 2615 | J34: ARSA | K34: BEREKETLİ AŞ | L34: SATIŞ KAPANDI | M34: SATIŞ KAPANDI | U34: 0.4 | V34: 0.8 | W34: 52394550 | AC34: 1248042055 | AD34: 136598-1758 | AE34: MELEK UZAMIŞ | AF34: VAR
A35: =F35&H35&I35 -> BEĞEL1043 | B35: DEĞİL - SATILDI | D35: MANİSA | E35: GÖRDES | F35: BEĞEL | G35: 374.32 | H35: 104 | I35: 3 | J35: ARSA | K35: BİLAL AKTAŞ | L35: SATILDI | M35: SATIŞ KAPANDI | N35: 2250 | O35: =ROUND(N35*G35,-4) -> 840000 | P35: =O35*0.9 -> 756000 | Q35: - | R35: - | S35: - | T35: - | AE35: UYGUR YENİ | AH35: TANER VARSAK | AK35: ELİF AKDOĞAN
A36: =F36&H36&I36 -> KAYAPA640419 | B36: STOK - İPOTEK | D36: BURSA | E36: NİLÜFER | F36: KAYAPA | G36: 650 | H36: 6404 | I36: 19 | J36: ARSA | K36: BİLAL AKTAŞ | L36: REZERVE | M36: STOKTA/İPOTEKLİ | N36: 20000 | O36: =ROUND(N36*G36,-4) -> 13000000 | P36: =O36*0.9 -> 11700000 | Q36: - | R36: - | W36: 95922296 | AN36: 31/12/2035
A37: =F37&H37&I37 -> KEMALİYE1023 | B37: STOK - KONS - ŞAHIS | C37: ÖNCELİKLİ | D37: MANİSA | E37: ALAŞEHİR | F37: KEMALİYE | G37: 425 | H37: 102 | I37: 3 | J37: ARSA | K37: BİLAL AKTAŞ | L37: İLAN BEKLİYOR | M37: SATILDI/2. SATIŞTA | N37: 3000 | O37: =ROUND(N37*G37,-4) -> 1280000 | P37: =O37*0.9 -> 1152000 | Q37: - | R37: - | S37: - | T37: - | U37: 0.3 | V37: 0.6 | AB37: İLAN | AC37: 1237613693 | AD37: 136598-1538 | AE37: NADİR HIDIR | AG37: 46752
A38: =F38&H38&I38 -> OKÇUGÖL1014 | B38: STOK - YATIRIMCI | C38: ÖNCELİKLİ | D38: BALIKESİR | E38: SUSURLUK | F38: OKÇUGÖL | G38: 465 | H38: 101 | I38: 4 | J38: ARSA | K38: DORTAGE AŞ | L38: İLAN BEKLİYOR | M38: SATILDI/2. SATIŞTA | N38: 4500 | O38: =ROUND(N38*G38,-4) -> 2090000 | P38: =O38*0.9 -> 1881000 | Q38: 4950 | R38: =ROUND(Q38*G38,-4) -> 2300000 | S38: 5445 | T38: =ROUND(S38*G38,-4) -> 2530000 | AE38: TANER SEZER
A39: =F39&H39&I39 -> SELİMAĞA1021 | B39: DEĞİL - SATILDI | D39: BALIKESİR | E39: DURSUNBEY | F39: SELİMAĞA | G39: 758.42 | H39: 102 | I39: 1 | J39: ARSA | K39: BİLAL AKTAŞ | L39: SATIŞ KAPANDI | M39: SATIŞ KAPANDI | AE39: ŞAHMETTİN
A40: =F40&H40&I40 -> REŞADİYE1572 | B40: STOK - KONS - ŞAHIS | C40: ÖNCELİKLİ | D40: BALIKESİR | E40: SUSURLUK | F40: REŞADİYE | G40: 412 | H40: 157 | I40: 2 | J40: ARSA | K40: BEREKETLİ AŞ | L40: İLAN BEKLİYOR | M40: SATILDI/2. SATIŞTA | N40: 2500 | O40: =ROUND(N40*G40,-4) -> 1030000 | P40: =O40*0.9 -> 927000 | Q40: - | R40: - | S40: - | T40: - | U40: 0.3 | V40: 0.5 | AB40: ilan | AE40: MUSTAFA MURAT COŞGUR
...

Sheet SHBN AKTİF İLANLAR
A1: İLAN NO | B1: DANIŞMAN | C1: İL | D1: İLÇE | E1: MAHALLE | F1: ADA | G1: PARSEL | H1: İLAN SAHİBİ | I1: SATIŞ DURUMU
A2: 1258765786 | B2: SEMİH | C2: ANKARA | D2: GÜDÜL | E2: GÜNEYCE | F2: 911 | G2: 4 | H2: STOK | I2: SATILABİLİR
A3: 1226760223 | B3: FURKAN | C3: ANKARA | D3: GÜDÜL | E3: GÜNEYCE | F3: 911 | G3: 19 | H3: STOK | I3: SATILABİLİR
A4: 1250555803 | B4: HAKAN | C4: ANKARA | D4: GÜDÜL | E4: GÜNEYCE | F4: 911 | G4: 20 | H4: STOK | I4: SATILABİLİR
A5: 1254031393 | B5: HAKAN | C5: AYDIN | D5: YENİPAZAR | E5: ALHAN | F5: 104 | G5: 2 | H5: STOK | I5: SATILABİLİR
A6: 1289507920 | B6: HAKAN | C6: AYDIN | D6: SÖKE | E6: ATBURGAZI | F6: 110 | G6: 3 | H6: STOK | I6: REZERVE
A7: 1294440362 | B7: SEMİH | C7: AYDIN | D7: SÖKE | E7: ATBURGAZI | F7: 110 | G7: 13 | H7: STOK | I7: SATILDI
A8: 1294495237 | B8: HAKAN | C8: AYDIN | D8: GERMENCİK | E8: CAMİİKEBİR | F8: 316 | G8: 21 | H8: STOK | I8: SATILABİLİR
A9: 1245400157 | B9: FURKAN | C9: BALIKESİR | D9: DURSUNBEY | E9: ÇELİKLER | F9: 116 | G9: 69 | H9: ŞAHIS | I9: SATILABİLİR
A10: 1289536587 | B10: SEMİH | C10: BALIKESİR | D10: SUSURLUK | E10: OKÇUGÖL | F10: 101 | G10: 4 | H10: ŞAHIS | I10: SATILABİLİR
A11: 1294646787 | B11: FURKAN | C11: BALIKESİR | D11: SUSURLUK | E11: REŞADİYE | F11: 165 | G11: 10 | H11: ŞAHIS | I11: SATILABİLİR
A12: 1244385254 | B12: HAKAN | C12: BALIKESİR | D12: SUSURLUK | E12: SÖVE | F12: 170 | G12: 18 | H12: ŞAHIS | I12: SATILABİLİR
A13: 1296041862 | B13: HAKAN | C13: BALIKESİR | D13: SUSURLUK | E13: OKÇUGÖL | F13: 101 | G13: 9 | H13: STOK | I13: SATILABİLİR
... A65: 1296435235 | B65: HAKAN | C65: BALIKESİR | D65: SUSURLUK | E65: KEPEKLER | F65: 132 | G65: 8 | H65: STOK | I65: SATILABİLİR

Sheet İLAN PLANLAMASI
A1: SAHİBİNDEN İLAN PLANLAMASI | B1: DEĞERLENDİRME - SONUÇ | C1: LİSTE GÜNCELLEME DURUMU
A2: GERMENCİK -SEMİH VE FURKAN GİRİLEBİLİR | B2: Furkan ilan girsin
A3: BİGA - FURKAN GİREBİLİR | B3: Furkan ilan girsin
A4: İSLAMLAR TEK PARSEL HİÇ KİMSEDE YOK | B4: Takasta birinden haber bekliyorduk, Semih daha beklemeyelim ilanı 5.500.000 TL den girersin, doping te basalım
A5: SEYİTLER - FURKAN VE SEMİH GİREBİLİR | B5: Semih ilan girsin
A6: BEĞEL 1 STOK VAR FURKAN- HAKAN GİREBİLİR | B6: Hakan abi ilan girsin | C6: YAPILDI - LİSTEYE YAZILDI
A7: KEMALİYE - SEMİH FURKAN GİREBİLİR | B7: Semih ilan girsin
A8: ERDEL - HAKAN-FURKAN EKLEYEBİLİR | B8: Hakan abi ilan girsin | C8: YAPILDI - LİSTEYE YAZILDI
A9: BÜYÜKPINAR- HAKAN GİREBİLİR | B9: Hakan abi ilan girsin | C9: YAPILDI - LİSTEYE YAZILDI
A10: İBİRLERDE 1 ADET DAHA GİRİLEBİLİR (SADECE BİLAL BEYDE) | B10: Bilal'dekini furkan alsın, semih bir ilan daha gir
A11: DAVUTLARDA HİÇ İLANIMIZ YOK | B11: Yer sahibi yerin satılması konusunda net değil, kalsın şuanlık
A12: KUVAYİ MİLLİYE - FURKAN 1 ADET GİREBİLİR | B12: Furkan ilan girsin
A13: TOYBELENE 1 İLAN DAHA GİRİLEBİLİR (SEMİH-FURKAN) | B13: Semih ilan girsin
A14: SULTANÇAYIR - HİÇ İLAN YOK | B14: Buradaki prefabrik ev, Hasan lots'tan ilan girelim
A15: DEMİRKAPI - HİÇ İLAN YOK | B15: Yer sahibi yerin satılması konusunda net değil, kalsın şuanlık
A16: BALIKLIDERE - FURKAN GİREBİLİR | B16: Furkan ilan girsin
A17: REŞADİYE - SEMİH GİREBİLİR | B17: Semih ilan girsin
A18: SÖVE - SEMİH'DE İLAN GİRİLEBİLİR | B18: Semih ilan girsin
A19: KEPEKLERDE HİÇ İLAN YOK | B19: Hakan abi ilan girsin | C19: YAPILDI - LİSTEYE YAZILDI

Sheet Sheet1
A1: Metrekare | B1: SATIŞ RAKAMI | C1: Ömer | D1: Bereketli | E1: BAKİYE | F1: SATIŞ DURUMU | G1: MÜŞTERİ | H1: ada | I1: parsel
A2: 627.94 | B2: 2500 | E2: 2500 | G2: murat | H2: 109 | I2: 7
A3: 663.98 | B3: 2500 | C3: 1222 | D3: 1278 | F3: SATILDI | G3: ALİ BAŞÇAVUS | H3: 109 | I3: 1
A4: 664.01 | B4: 2400 | C4: 1300 | D4: 700 | E4: 400 | F4: SATILDI | G4: MUTTALİP BAŞÇAVUŞ | H4: 109 | I4: 2 | J4: taksit ve senet yapıldı takip edilecek
A5: 671.98 | B5: 2618 | D5: 2268 | E5: 350 | F5: satıldı | G5: yaşar kara | H5: 109 | I5: 9
A6: 671.98 | B6: 2250 | E6: 2250 | F6: SATILDI | G6: MENEKŞE BULAT | H6: 109 | I6: 10 | J6: 4200 yarın gelecek 300 bin tl taksidi biz takip edeceğiz
A7: 671.99 | B7: 2500 | E7: 2500 | G7: murat | H7: 109 | I7: 8 | J7: 4200 yarın gelecek 300 bin tl taksidi biz takip edeceğiz
A8: 672.05 | B8: 2250 | E8: 2250 | F8: SATILDI | G8: MENEKŞE BULAT | H8: 109 | I8: 3 | J8: 6000 yarın gelecek ömerin hesabına gidecek 1750 taksit 5 tane 300 1 tane 250 taksitleri aldıkça 150 şer bin 3 taksit 450 bin tl komisyon ödeyeceğiz
A9: 672.07 | B9: 2500 | D9: 2500 | F9: SATILDI | G9: ALİ/MURAT BAŞÇAVUŞ | H9: 109 | I9: 4
A10: 672.13 | B10: 2600 | D10: 2600 | F10: SATILDI | G10: GÖKHAN ERDİNÇ | H10: 109 | I10: 5
A11: 704.82 | B11: 2750 | E11: 2750 | G11: murat | H11: 109 | I11: 6
A12: 751.94 | B12: 3600 | D12: 1800 | E12: 1800 | F12: SATILDI | G12: BİRANT AKKUYU | H12: 101 | I12: 6 | J12: 7*50 bin taksit ve senet yapıldı
B17: SATIŞ RAKAMI | C17: Ömer | D17: Bereketli | E17: BAKİYE | F17: SATIŞ DURUMU | G17: MÜŞTERİ
A18: 663.98 | B18: 2500 | C18: 1222 | D18: 1278 | F18: SATILDI | G18: ALİ BAŞÇAVUS | H18: 109 | I18: 1
A19: 672.07 | B19: 2500 | D19: 2500 | F19: SATILDI | G19: ALİ/MURAT BAŞÇAVUŞ | H19: 109 | I19: 4
A20: 751.94 | B20: 3600 | D20: 1800 | E20: 1800 | F20: SATILDI | G20: BİRANT AKKUYU | H20: 101 | I20: 6
A21: 672.13 | B21: 2600 | D21: 2600 | F21: SATILDI | G21: GÖKHAN ERDİNÇ | H21: 109 | I21: 5
A22: 671.98 | B22: 2250 | D22: 2100 | E22: 150 | F22: SATILDI | G22: MENEKŞE BULAT | H22: 109 | I22: 10
A23: 672.05 | B23: 2250 | D23: 2100 | E23: 150 | F23: SATILDI | G23: MENEKŞE BULAT | H23: 109 | I23: 3
A24: 627.94 | B24: 2500 | D24: 2000 | E24: 500 | G24: murat | H24: 109 | I24: 7
A25: 671.99 | B25: 2500 | D25: 2000 | E25: 500 | G25: murat | H25: 109 | I25: 8
A26: 704.82 | B26: 2750 | D26: 2000 | E26: 750 | G26: murat | H26: 109 | I26: 6
A27: 664.01 | B27: 2400 | C27: 1300 | D27: 700 | E27: 400 | F27: SATILDI | G27: MUTTALİP BAŞÇAVUŞ | H27: 109 | I27: 2
A28: 671.98 | B28: 2618 | D28: 2268 | E28: 350 | F28: satıldı | G28: yaşar kara | H28: 109 | I28: 9

Sheet inköyler
B5: KOD | C5: STOK TÜRÜ | D5: ÖNCELİK | E5: İL | F5: İLÇE | G5: MAHALLE | H5: ALAN | I5: ADA | J5: PARSEL | K5: NİTELİK | L5: ŞİRKET | M5: DURUM | N5: DURUM 2 | O5: M2 FİYATI
B6: =G6&I6&J6 -> İNKÖY48681-7 | C6: STOK - HAZIR | D6: ÖNCELİKLİ | E6: KÜTAHYA | F6: MERKEZ | G6: İNKÖY | H6: 150 | I6: 4868 | J6: 1-7 | K6: ARSA | L6: BEREKETLİ AŞ | M6: İLAN BEKLİYOR | N6: STOKTA | O6: =P6/H6 -> 0
B7: =G7&I7&J7 -> İNKÖY48681-8 | C7: STOK - HAZIR | D7: ÖNCELİKLİ | E7: KÜTAHYA | F7: MERKEZ | G7: İNKÖY | H7: 150 | I7: 4868 | J7: 1-8 | K7: ARSA | L7: BEREKETLİ AŞ | M7: İLAN BEKLİYOR | N7: STOKTA | O7: =P7/H7 -> 0
B8: =G8&I8&J8 -> İNKÖY48681-9 | C8: STOK - HAZIR | D8: ÖNCELİKLİ | E8: KÜTAHYA | F8: MERKEZ | G8: İNKÖY | H8: 150 | I8: 4868 | J8: 1-9 | K8: ARSA | L8: BEREKETLİ AŞ | M8: İLAN BEKLİYOR | N8: STOKTA | O8: =P8/H8 -> 0
B9: =G9&I9&J9 -> İNKÖY48681-10 | C9: STOK - HAZIR | D9: ÖNCELİKLİ | E9: KÜTAHYA | F9: MERKEZ | G9: İNKÖY | H9: 150 | I9: 4868 | J9: 1-10 | K9: ARSA | L9: BEREKETLİ AŞ | M9: İLAN BEKLİYOR | N9: STOKTA | O9: =P9/H9 -> 0
B10: =G10&I10&J10 -> İNKÖY48681-11 | C10: STOK - HAZIR | D10: ÖNCELİKLİ | E10: KÜTAHYA | F10: MERKEZ | G10: İNKÖY | H10: 150 | I10: 4868 | J10: 1-11 | K10: ARSA | L10: BEREKETLİ AŞ | M10: İLAN BEKLİYOR | N10: STOKTA | O10: =P10/H10 -> 0
B11: =G11&I11&J11 -> İNKÖY48681-1 | C11: DEĞİL - SATILDI | E11: KÜTAHYA | F11: MERKEZ | G11: İNKÖY | H11: 150 | I11: 4868 | J11: 1-1 | K11: ARSA | L11: BEREKETLİ AŞ | M11: SATIŞ KAPANDI | N11: SATIŞ KAPANDI | O11: =P11/H11 -> 0
B12: =G12&I12&J12 -> İNKÖY48681-2 | C12: DEĞİL - SATILDI | E12: KÜTAHYA | F12: MERKEZ | G12: İNKÖY | H12: 150 | I12: 4868 | J12: 1-2 | K12: ARSA | L12: BEREKETLİ AŞ | M12: SATIŞ KAPANDI | N12: SATIŞ KAPANDI | O12: =P12/H12 -> 0
B13: =G13&I13&J13 -> İNKÖY48681-3 | C13: DEĞİL - SATILDI | E13: KÜTAHYA | F13: MERKEZ | G13: İNKÖY | H13: 150 | I13: 4868 | J13: 1-3 | K13: ARSA | L13: BEREKETLİ AŞ | M13: SATIŞ KAPANDI | N13: SATIŞ KAPANDI | O13: =P13/H13 -> 0
B14: =G14&I14&J14 -> İNKÖY48681-4 | C14: DEĞİL - SATILDI | E14: KÜTAHYA | F14: MERKEZ | G14: İNKÖY | H14: 150 | I14: 4868 | J14: 1-4 | K14: ARSA | L14: BEREKETLİ AŞ | M14: SATIŞ KAPANDI | N14: SATIŞ KAPANDI | O14: =P14/H14 -> 0
B15: =G15&I15&J15 -> İNKÖY48681-5 | C15: DEĞİL - SATILDI | E15: KÜTAHYA | F15: MERKEZ | G15: İNKÖY | H15: 150 | I15: 4868 | J15: 1-5 | K15: ARSA | L15: BEREKETLİ AŞ | M15: İLAN BEKLİYOR | N15: STOKTA | O15: =P15/H15 -> 0
B16: =G16&I16&J16 -> İNKÖY48681-12 | C16: STOK - HAZIR | D16: ÖNCELİKLİ | E16: KÜTAHYA | F16: MERKEZ | G16: İNKÖY | H16: 150 | I16: 4868 | J16: 1-12 | K16: ARSA | L16: BEREKETLİ AŞ | M16: İLAN BEKLİYOR | N16: STOKTA | O16: =P16/H16 -> 0
B17: =G17&I17&J17 -> İNKÖY48681-13 | C17: STOK - HAZIR | D17: ÖNCELİKLİ | E17: KÜTAHYA | F17: MERKEZ | G17: İNKÖY | H17: 150 | I17: 4868 | J17: 1-13 | K17: ARSA | L17: BEREKETLİ AŞ | M17: İLAN BEKLİYOR | N17: STOKTA | O17: =P17/H17 -> 0
B18: =G18&I18&J18 -> İNKÖY48681-14 | C18: STOK - HAZIR | D18: ÖNCELİKLİ | E18: KÜTAHYA | F18: MERKEZ | G18: İNKÖY | H18: 150 | I18: 4868 | J18: 1-14 | K18: ARSA | L18: BEREKETLİ AŞ | M18: İLAN BEKLİYOR | N18: STOKTA | O18: =P18/H18 -> 0
B19: =G19&I19&J19 -> İNKÖY48681-15 | C19: STOK - HAZIR | D19: ÖNCELİKLİ | E19: KÜTAHYA | F19: MERKEZ | G19: İNKÖY | H19: 150 | I19: 4868 | J19: 1-15 | K19: ARSA | L19: BEREKETLİ AŞ | M19: İLAN BEKLİYOR | N19: STOKTA | O19: =P19/H19 -> 0
B20: =G20&I20&J20 -> İNKÖY48681-16 | C20: STOK - HAZIR | D20: ÖNCELİKLİ | E20: KÜTAHYA | F20: MERKEZ | G20: İNKÖY | H20: 150 | I20: 4868 | J20: 1-16 | K20: ARSA | L20: BEREKETLİ AŞ | M20: İLAN BEKLİYOR | N20: STOKTA | O20: =P20/H20 -> 0
B21: =G21&I21&J21 -> İNKÖY48681-17 | C21: STOK - HAZIR | D21: ÖNCELİKLİ | E21: KÜTAHYA | F21: MERKEZ | G21: İNKÖY | H21: 150 | I21: 4868 | J21: 1-17 | K21: ARSA | L21: BEREKETLİ AŞ | M21: İLAN BEKLİYOR | N21: STOKTA | O21: =P21/H21 -> 0
B22: =G22&I22&J22 -> İNKÖY48681-18 | C22: STOK - HAZIR | D22: ÖNCELİKLİ | E22: KÜTAHYA | F22: MERKEZ | G22: İNKÖY | H22: 150 | I22: 4868 | J22: 1-18 | K22: ARSA | L22: BEREKETLİ AŞ | M22: İLAN BEKLİYOR | N22: STOKTA | O22: =P22/H22 -> 0
B23: =G23&I23&J23 -> İNKÖY48681-19 | C23: STOK - HAZIR | D23: ÖNCELİKLİ | E23: KÜTAHYA | F23: MERKEZ | G23: İNKÖY | H23: 150 | I23: 4868 | J23: 1-19 | K23: ARSA | L23: BEREKETLİ AŞ | M23: İLAN BEKLİYOR | N23: STOKTA | O23: =P23/H23 -> 0
B24: =G24&I24&J24 -> İNKÖY48681-20 | C24: STOK - HAZIR | D24: ÖNCELİKLİ | E24: KÜTAHYA | F24: MERKEZ | G24: İNKÖY | H24: 150 | I24: 4868 | J24: 1-20 | K24: ARSA | L24: BEREKETLİ AŞ | M24: İLAN BEKLİYOR | N24: STOKTA | O24: =P24/H24 -> 0
B25: =G25&I25&J25 -> İNKÖY48682-1 | C25: STOK - HAZIR | D25: ÖNCELİKLİ | E25: KÜTAHYA | F25: MERKEZ | G25: İNKÖY | H25: 150 | I25: 4868 | J25: 2-1 | K25: ARSA | L25: BEREKETLİ AŞ | M25: İLAN BEKLİYOR | N25: STOKTA | O25: =P25/H25 -> 0
B26: =G26&I26&J26 -> İNKÖY48682-2 | C26: STOK - HAZIR | D26: ÖNCELİKLİ | E26: KÜTAHYA | F26: MERKEZ | G26: İNKÖY | H26: 150 | I26: 4868 | J26: 2-2 | K26: ARSA | L26: BEREKETLİ AŞ | M26: İLAN BEKLİYOR | N26: STOKTA | O26: =P26/H26 -> 0
B27: =G27&I27&J27 -> İNKÖY48682-3 | C27: STOK - HAZIR | D27: ÖNCELİKLİ | E27: KÜTAHYA | F27: MERKEZ | G27: İNKÖY | H27: 150 | I27: 4868 | J27: 2-3 | K27: ARSA | L27: BEREKETLİ AŞ | M27: İLAN BEKLİYOR | N27: STOKTA | O27: =P27/H27 -> 0
... B44: =G44&I44&J44 -> İNKÖY48682-20 | C44: STOK - HAZIR | D44: ÖNCELİKLİ | E44: KÜTAHYA | F44: MERKEZ | G44: İNKÖY | H44: 150 | I44: 4868 | J44: 2-20 | K44: ARSA | L44: BEREKETLİ AŞ | M44: İLAN BEKLİYOR | N44: STOKTA | O44: =P44/H44 -> 0
